Workbook

Sheet Reset
A1: Field | B1: Value | C1: Notes
A2: Reset name | B2: Spring Reset MAR26
A3: Date suffix | B3: MAR26
A4: Prior reset to clone | B4: Fall Reset SEP25 | C4: Tool inherits unchanged fixtures from this reset
A5: LOB | C5: iPhone / iPad / Mac / Watch / AVP — LOB owner fills this in
A6: Mode | B6: T-12 forecast | C6: or "T-6 finalized" — controls buffer application
A7: Buffer % | B7: 10 | C7: Applied at T-12 forecast mode; 0 at finalized

Sheet New Products
A1: Code | B1: Color | C1: Notes

Sheet Per-Fixture Quantities
A1: Fixture Type | B1: Size | C1: Class | D1: =IF(ISBLANK('New Products'!A2),"",'New Products'!A2&" "&'New Products'!B2) | E1: =IF(ISBLANK('New Products'!A3),"",'New Products'!A3&" "&'New Products'!B3) | F1: =IF(ISBLANK('New Products'!A4),"",'New Products'!A4&" "&'New Products'!B4) | G1: =IF(ISBLANK('New Products'!A5),"",'New Products'!A5&" "&'New Products'!B5) | H1: =IF(ISBLANK('New Products'!A6),"",'New Products'!A6&" "&'New Products'!B6) | I1: =IF(ISBLANK('New Products'!A7),"",'New Products'!A7&" "&'New Products'!B7) | J1: =IF(ISBLANK('New Products'!A8),"",'New Products'!A8&" "&'New Products'!B8) | K1: =IF(ISBLANK('New Products'!A9),"",'New Products'!A9&" "&'New Products'!B9) | L1: =IF(ISBLANK('New Products'!A10),"",'New Products'!A10&" "&'New Products'!B10) | M1: =IF(ISBLANK('New Products'!A11),"",'New Products'!A11&" "&'New Products'!B11) | N1: =IF(ISBLANK('New Products'!A12),"",'New Products'!A12&" "&'New Products'!B12) | O1: =IF(ISBLANK('New Products'!A13),"",'New Products'!A13&" "&'New Products'!B13) | P1: =IF(ISBLANK('New Products'!A14),"",'New Products'!A14&" "&'New Products'!B14) | Q1: =IF(ISBLANK('New Products'!A15),"",'New Products'!A15&" "&'New Products'!B15) | R1: =IF(ISBLANK('New Products'!A16),"",'New Products'!A16&" "&'New Products'!B16) | S1: =IF(ISBLANK('New Products'!A17),"",'New Products'!A17&" "&'New Products'!B17) | T1: =IF(ISBLANK('New Products'!A18),"",'New Products'!A18&" "&'New Products'!B18) | U1: =IF(ISBLANK('New Products'!A19),"",'New Products'!A19&" "&'New Products'!B19) | V1: =IF(ISBLANK('New Products'!A20),"",'New Products'!A20&" "&'New Products'!B20) | W1: =IF(ISBLANK('New Products'!A21),"",'New Products'!A21&" "&'New Products'!B21) | X1: Notes
A2: ━━━━━ iPhone ━━━━━
A3: iPhone Assortment | B3: 7 ft | C3: Table
A4: iPhone Assortment | B4: 8 ft | C4: Table
A5: iPhone Assortment | B5: 10 ft | C5: Table
A6: iPhone Assortment | B6: 12 ft | C6: Table
A7: iPhone Assortment | B7: 24-34 ft | C7: Wall
A8: iPhone Hero Comparison | B8: 10 ft | C8: Wall
A9: iPhone Hero Comparison | B9: 12-17 ft | C9: Wall
A10: iPhone Hero Comparison | B10: 18-23 ft | C10: Wall
A11: iPhone Hero Comparison | B11: 24-34 ft | C11: Wall
A12: iPhone Hero Comparison 1 | B12: 7 ft | C12: Table
A13: iPhone Hero Comparison 1 | B13: 8 ft | C13: Table
A14: iPhone Hero Comparison 1 | B14: 10 ft | C14: Table
... A33: Service & Learning Merchandised | B33: Various | C33: S&L
A34: ━━━━━ iPad ━━━━━
A35: iPad Asst Table | B35: 7 ft | C35: Table
A36: iPad Asst Table | B36: 8 ft | C36: Table
A37: iPad Asst Table | B37: 10 ft | C37: Table
A38: iPad Asst Table | B38: 12 ft | C38: Table
A39: iPad Asst Table | B39: 15 ft | C39: Table
A40: iPad Comp Table | B40: 7 ft | C40: Table
A41: iPad Comp Table | B41: 8 ft | C41: Table
A42: iPad Comp Table | B42: 10 ft | C42: Table
A43: iPad Comp Table | B43: 12 ft | C43: Table
A44: iPad Comp Table | B44: 15 ft | C44: Table
A45: iPad Comp Wall | B45: 10 ft | C45: Wall
A46: iPad Comp Wall | B46: 12-17 ft | C46: Wall
... A48: iPad Comp Wall | B48: 24-34 ft | C48: Wall
A49: ━━━━━ Mac ━━━━━
A50: Desktop Comp Table | B50: 7 ft | C50: Table
A51: Desktop Comp Table | B51: 8 ft | C51: Table
A52: Desktop Comp Table | B52: 10 ft | C52: Table
A53: Desktop Comp Table | B53: 12 ft | C53: Table
A54: Desktop Comp Table | B54: 15 ft | C54: Table
A55: Desktop Comp Wall | B55: 10 ft | C55: Wall
A56: Desktop Comp Wall | B56: 12-17 ft | C56: Wall
A57: Desktop Comp Wall | B57: 18-23 ft | C57: Wall
A58: Desktop Comp Wall | B58: 24-34 ft | C58: Wall
A59: Mac Comp Table | B59: 7 ft | C59: Table
...

Sheet Avenue Quantities
A1: Category | B1: Canonical Variant | C1: =IF(ISBLANK('New Products'!A2),"",'New Products'!A2&" "&'New Products'!B2) | D1: =IF(ISBLANK('New Products'!A3),"",'New Products'!A3&" "&'New Products'!B3) | E1: =IF(ISBLANK('New Products'!A4),"",'New Products'!A4&" "&'New Products'!B4) | F1: =IF(ISBLANK('New Products'!A5),"",'New Products'!A5&" "&'New Products'!B5) | G1: =IF(ISBLANK('New Products'!A6),"",'New Products'!A6&" "&'New Products'!B6) | H1: =IF(ISBLANK('New Products'!A7),"",'New Products'!A7&" "&'New Products'!B7) | I1: =IF(ISBLANK('New Products'!A8),"",'New Products'!A8&" "&'New Products'!B8) | J1: =IF(ISBLANK('New Products'!A9),"",'New Products'!A9&" "&'New Products'!B9) | K1: =IF(ISBLANK('New Products'!A10),"",'New Products'!A10&" "&'New Products'!B10) | L1: =IF(ISBLANK('New Products'!A11),"",'New Products'!A11&" "&'New Products'!B11) | M1: =IF(ISBLANK('New Products'!A12),"",'New Products'!A12&" "&'New Products'!B12) | N1: =IF(ISBLANK('New Products'!A13),"",'New Products'!A13&" "&'New Products'!B13) | O1: =IF(ISBLANK('New Products'!A14),"",'New Products'!A14&" "&'New Products'!B14) | P1: =IF(ISBLANK('New Products'!A15),"",'New Products'!A15&" "&'New Products'!B15) | Q1: =IF(ISBLANK('New Products'!A16),"",'New Products'!A16&" "&'New Products'!B16) | R1: =IF(ISBLANK('New Products'!A17),"",'New Products'!A17&" "&'New Products'!B17) | S1: =IF(ISBLANK('New Products'!A18),"",'New Products'!A18&" "&'New Products'!B18) | T1: =IF(ISBLANK('New Products'!A19),"",'New Products'!A19&" "&'New Products'!B19) | U1: =IF(ISBLANK('New Products'!A20),"",'New Products'!A20&" "&'New Products'!B20) | V1: =IF(ISBLANK('New Products'!A21),"",'New Products'!A21&" "&'New Products'!B21) | W1: Notes
A2: ━━━━━ Vin C ━━━━━
A3: FEATURE BAY | B3: FB1
A4: FEATURE BAY | B4: FB2
A5: FEATURE BAY | B5: FB3
A6: FEATURE BAY | B6: FB4
A7: FEATURE BAY | B7: FB5
A8: FEATURE BAY | B8: FB6
A9: ━━━━━ Vin D ━━━━━
A10: AIRPODS | B10: AIRPODS_5FT
A11: AIRPODS | B11: AIRPODS_10FT
A12: AIRPODS | B12: AIRPODS_15FT
A13: AIRTAG | B13: AIRTAG_5FT
A14: AIRTAG | B14: AIRTAG_10FT
A15: APPLE MUSIC | B15: APPLE_MUSIC_5FT
A16: APPLE MUSIC | B16: APPLE_MUSIC_HPM_5FT
A17: APPLE MUSIC | B17: APPLE_MUSIC_10FT
A18: APPLE MUSIC | B18: APPLE_MUSIC_15FT
A19: APPLE TV PLUS | B19: TV_PLUS_5FT
A20: APPLE TV PLUS | B20: TV_PLUS_7.5FT
A21: APPLE TV PLUS | B21: TV_PLUS_10FT
... A45: WATCH | B45: WATCH_15FT
A46: ━━━━━ Vin E ━━━━━
A47: AIRPODS | B47: E_AIRPODS_10FT
A48: APPLE MUSIC | B48: E_APPLE_MUSIC_10FT
A49: APPLE TV PLUS | B49: E_TV_PLUS_10FT
A50: APPLE VISION PRO | B50: E_AVP_10FT
A51: IPAD HERO | B51: E_IPAD_ACC_10FT
A52: IPHONE HERO | B52: E_IPHONE_MAC_ACC_10FT
A53: WATCH | B53: E_WATCH_10FT
A54: WATCH | B54: E_WATCH_STUDIO_10FT
A55: ━━━━━ iPhone Cases ━━━━━
A56: IPHONE CASES | B56: 10FT (D.2)
A57: IPHONE CASES | B57: 10FT (Vin E)
A58: IPHONE CASES | B58: 15FT (D.2)
A59: IPHONE CASES | B59: 20FT (D.2)
A60: IPHONE CASES | B60: 20FT (Vin E)
A61: IPHONE CASES | B61: 30FT (D.2)
A62: TOTAL (per-avenue qty sum) | C62: =SUM(C2:C61) | D62: =SUM(D2:D61) | E62: =SUM(E2:E61) | F62: =SUM(F2:F61) | G62: =SUM(G2:G61) | H62: =SUM(H2:H61) | I62: =SUM(I2:I61) | J62: =SUM(J2:J61) | ... V62: =SUM(V2:V61)

Sheet Programs
A1: Program | B1: Store # | C1: Store Name | D1: Count | E1: Notes
A2: ━━━━━ Today at Apple High Profile ━━━━━
A3: Today at Apple High Profile | B3: R032 | C3: SoHo | D3: 1
A4: Today at Apple High Profile | B4: R035 | C4: Michigan Avenue | D4: 1
A5: Today at Apple High Profile | B5: R050 | C5: The Grove | D5: 1
A6: Today at Apple High Profile | B6: R051 | C6: Third Street Promenade | D6: 1
A7: Today at Apple High Profile | B7: R075 | C7: Union Square (San Francisco) | D7: 1
A8: Today at Apple High Profile | B8: R087 | C8: Aventura | D8: 1
A9: Today at Apple High Profile | B9: R092 | C9: Regent Street | D9: 1
A10: Today at Apple High Profile | B10: R095 | C10: Fifth Avenue (5th) | D10: 1
A11: Today at Apple High Profile | B11: R224 | C11: Omotesando (Tokyo) | D11: 1
A12: Today at Apple High Profile | B12: R238 | C12: Sydney (George St) | D12: 1
A13: Today at Apple High Profile | B13: R245 | C13: Covent Garden | D13: 1
A14: Today at Apple High Profile | B14: R320 | C14: Sanlitun (Beijing) | D14: 1
... A36: Today at Apple High Profile | B36: R744 | C36: APPLE BKC | D36: 1
A37: ━━━━━ Today at Apple ━━━━━
A38: ━━━━━ Boardrooms ━━━━━
A39: Boardrooms | B39: R048 | C39: FUKUOKA | D39: 1
A40: Boardrooms | B40: R092 | C40: Regent Street | D40: 1
A41: Boardrooms | B41: R118 | C41: BIRMINGHAM | D41: 1
A42: Boardrooms | B42: R119 | C42: SHIBUYA | D42: 1
A43: Boardrooms | B43: R135 | C43: GLASGOW | D43: 1
A44: Boardrooms | B44: R180 | C44: CHADSTONE | D44: 1
A45: Boardrooms | B45: R238 | C45: SYDNEY | D45: 1
A46: Boardrooms | B46: R245 | C46: Covent Garden | D46: 1
A47: Boardrooms | B47: R320 | C47: SANLITUN | D47: 1
A48: Boardrooms | B48: R358 | C48: Kurfurstendamm | D48: 1
A49: Boardrooms | B49: R368 | C49: Passeig de Gracia | D49: 1
A50: Boardrooms | B50: R382 | C50: VIA DEL CORSO | D50: 1
... A80: Boardrooms | B80: R744 | C80: APPLE BKC, G1-G2, F1-F2, S1-S2 | D80: 1
A81: ━━━━━ On Demand Demo ━━━━━
A82: ━━━━━ Flagship ━━━━━
A83: Flagship | B83: R006 | C83: Lenox Square | D83: 1
A84: Flagship | B84: R014 | C84: Broadway Plaza (Walnut Creek) | D84: 1
A85: Flagship | B85: R031 | C85: Scottsdale Fashion Square (Biltmore) | D85: 1
A86: Flagship | B86: R032 | C86: SoHo | D86: 1
A87: Flagship | B87: R039 | C87: Valley Fair | D87: 1
A88: Flagship | B88: R048 | C88: Fukuoka Tenjin | D88: 1
A89: Flagship | B89: R050 | C89: The Grove | D89: 1
A90: Flagship | B90: R051 | C90: Third Street Promenade | D90: 1
...

Sheet Program Ratios
A1: Program | B1: Applies to | C1: =IF(ISBLANK('New Products'!A2),"",'New Products'!A2&" "&'New Products'!B2) | D1: =IF(ISBLANK('New Products'!A3),"",'New Products'!A3&" "&'New Products'!B3) | E1: =IF(ISBLANK('New Products'!A4),"",'New Products'!A4&" "&'New Products'!B4) | F1: =IF(ISBLANK('New Products'!A5),"",'New Products'!A5&" "&'New Products'!B5) | G1: =IF(ISBLANK('New Products'!A6),"",'New Products'!A6&" "&'New Products'!B6) | H1: =IF(ISBLANK('New Products'!A7),"",'New Products'!A7&" "&'New Products'!B7) | I1: =IF(ISBLANK('New Products'!A8),"",'New Products'!A8&" "&'New Products'!B8) | J1: =IF(ISBLANK('New Products'!A9),"",'New Products'!A9&" "&'New Products'!B9) | K1: =IF(ISBLANK('New Products'!A10),"",'New Products'!A10&" "&'New Products'!B10) | L1: =IF(ISBLANK('New Products'!A11),"",'New Products'!A11&" "&'New Products'!B11) | M1: =IF(ISBLANK('New Products'!A12),"",'New Products'!A12&" "&'New Products'!B12) | N1: =IF(ISBLANK('New Products'!A13),"",'New Products'!A13&" "&'New Products'!B13) | O1: =IF(ISBLANK('New Products'!A14),"",'New Products'!A14&" "&'New Products'!B14) | P1: =IF(ISBLANK('New Products'!A15),"",'New Products'!A15&" "&'New Products'!B15) | Q1: =IF(ISBLANK('New Products'!A16),"",'New Products'!A16&" "&'New Products'!B16) | R1: =IF(ISBLANK('New Products'!A17),"",'New Products'!A17&" "&'New Products'!B17) | S1: =IF(ISBLANK('New Products'!A18),"",'New Products'!A18&" "&'New Products'!B18) | T1: =IF(ISBLANK('New Products'!A19),"",'New Products'!A19&" "&'New Products'!B19) | U1: =IF(ISBLANK('New Products'!A20),"",'New Products'!A20&" "&'New Products'!B20) | V1: =IF(ISBLANK('New Products'!A21),"",'New Products'!A21&" "&'New Products'!B21) | W1: Notes
A2: Today at Apple High Profile | B2: Listed stores only
A3: Today at Apple | B3: All stores
A4: Boardrooms | B4: Listed stores only
A5: On Demand Demo | B5: All stores
A6: Flagship | B6: Listed stores only
A7: Flagship+ | B7: Listed stores only
A8: Accessibility Equipment | B8: All stores
A9: Apple Vision Pro Equipment | B9: Listed stores only

Sheet Fixture Counts
B1: NSOs
K2: TOTAL | L2: 512 | M2: 25 | N2: 212 | O2: 35 | P2: 229 | Q2: 16 | R2: 544 | S2: 609 | T2: 635 | U2: 315 | V2: 1 | W2: 429 | X2: 314 | Y2: 210 | Z2: 55 | AA2: 255 | AB2: 454 | AC2: 158 | AD2: 571 | AE2: 39 | AF2: 63 | AG2: 69 | AH2: 85 | AI2: 49 | AJ2: 256 | AK2: 159 | AL2: 121 | AM2: 10 | AN2: 205 | AO2: 362 | AP2: 123 | AQ2: 55 | AR2: 18 | AS2: 223 | AT2: 59 | AU2: 110 | AV2: 425 | AW2: 422 | AX2: 112 | AY2: 11 | AZ2: 543 | BA2: 121
A4: 539 | B4: Geo | C4: Country | D4: Store Number | E4: Store Name | F4: Store Type | G4: Flagship Stores | H4: Store Layout Size | I4: Table Type | J4: Table Size | K4: Wall Size (merchandise length) | L4: Spring Spotlight Table | M4: Spring Spotlight Wall | N4: Apple Vision Pro Table | O4: Apple Vision Pro Wall | P4: Apple Vision Pro Combined | Q4: Apple Vision Pro Experience | R4: AVP Center Display | S4: iPhone Assortment | T4: iPhone Hero Table 1 (7'-12') | U4: iPhone Hero Table 2 (7'-12') | V4: iPhone Hero Table (15' EMEIA only) | W4: iPhone Legacy Table | X4: iPhone Hero Wall | Y4: iPhone Legacy Wall | Z4: iPhone Hero and Legacy Wall | AA4: iPad Asst Table | AB4: iPad Comp Table | AC4: iPad Comp Wall | AD4: Mac Comp Table | AE4: Mac Comp Wall | AF4: iMac 24-inch Colors Table | AG4: iMac 24-inch Colors Wall | AH4: Desktop Comp Table | AI4: Desktop Comp Wall | AJ4: iMac 24 Colors | Desktop Comp Table | AK4: iMac 24 Colors | Desktop Comp Wall | AL4: Mac | iPad Table 1 | AM4: Mac | iPad Table 2 | AN4: Mac | iPad Wall | AO4: Continuity Table | AP4: Continuity Wall | AQ4: Continuity Desktop Alt (1) Touchpoint | AR4: Continuity Desktop Alt (2) Touchpoints | AS4: Apple TV Wall (2 TVs) | AT4: Apple TV Wall (1 TV) | AU4: HomePod Wall | AV4: Watch Discovery | AW4: Watch Personalisation | AX4: Watch Combined | AY4: Watch Experience Table | AZ4: Watch Center Display | BA4: Moves
A5: 1 | B5: AMR | C5: USA | D5: R001 | E5: Glendale Galleria | F5: Vintage C | G5: Apple Store | H5: Large | I5: Slug | J5: 10' | K5: 15' | L5: 1 | M5: 0 | N5: 0 | O5: 0 | P5: 1 | Q5: 0 | R5: 1 | S5: 1 | T5: 1 | U5: 1 | V5: 0 | W5: 0 | X5: 1 | Y5: 1 | Z5: 0 | AA5: 0 | AB5: 0 | AC5: 1 | AD5: 1 | AE5: 0 | AF5: 0 | AG5: 0 | AH5: 0 | AI5: 0 | AJ5: 0 | AK5: 1 | AL5: 0 | AM5: 0 | AN5: 1 | AO5: 1 | AP5: 0 | AQ5: 0 | AR5: 0 | AS5: 1 | AT5: 0 | AU5: 0 | AV5: 1 | AW5: 1 | AX5: 0 | AY5: 0 | AZ5: 1
A6: 1 | B6: AMR | C6: USA | D6: R002 | E6: Palo Alto | F6: Vintage D | G6: Apple Store+ | H6: Medium | I6: Slug | J6: 10' | K6: - | L6: 1 | M6: 0 | N6: 1 | O6: 0 | P6: 0 | Q6: 0 | R6: 1 | S6: 1 | T6: 1 | U6: 0 | V6: 0 | W6: 1 | X6: 0 | Y6: 0 | Z6: 0 | AA6: 0 | AB6: 1 | AC6: 0 | AD6: 1 | AE6: 0 | AF6: 0 | AG6: 0 | AH6: 0 | AI6: 0 | AJ6: 1 | AK6: 0 | AL6: 0 | AM6: 0 | AN6: 0 | AO6: 0 | AP6: 0 | AQ6: 1 | AR6: 0 | AS6: 0 | AT6: 0 | AU6: 0 | AV6: 1 | AW6: 1 | AX6: 0 | AY6: 0 | AZ6: 1
A7: 1 | B7: AMR | C7: USA | D7: R003 | E7: Bellevue Square | F7: Vintage C | G7: Apple Store | H7: X-Large | I7: Slug | J7: 10' | K7: 15' | L7: 1 | M7: 0 | N7: 1 | O7: 0 | P7: 0 | Q7: 0 | R7: 1 | S7: 1 | T7: 3 | U7: 1 | V7: 0 | W7: 1 | X7: 1 | Y7: 0 | Z7: 1 | AA7: 1 | AB7: 1 | AC7: 0 | AD7: 2 | AE7: 0 | AF7: 0 | AG7: 1 | AH7: 0 | AI7: 1 | AJ7: 0 | AK7: 0 | AL7: 1 | AM7: 0 | AN7: 1 | AO7: 2 | AP7: 0 | AQ7: 0 | AR7: 0 | AS7: 1 | AT7: 0 | AU7: 0 | AV7: 1 | AW7: 1 | AX7: 0 | AY7: 0 | AZ7: 1
A8: 1 | B8: AMR | C8: USA | D8: R004 | E8: South Coast Plaza | F8: Vintage C | G8: Temp | H8: Large | I8: Slug | J8: 10' | K8: 15' | L8: 1 | M8: 0 | N8: 0 | O8: 0 | P8: 1 | Q8: 0 | R8: 1 | S8: 1 | T8: 1 | U8: 0 | V8: 0 | W8: 1 | X8: 1 | Y8: 0 | Z8: 0 | AA8: 0 | AB8: 1 | AC8: 0 | AD8: 1 | AE8: 0 | AF8: 0 | AG8: 0 | AH8: 0 | AI8: 0 | AJ8: 0 | AK8: 1 | AL8: 0 | AM8: 0 | AN8: 1 | AO8: 0 | AP8: 1 | AQ8: 0 | AR8: 0 | AS8: 1 | AT8: 0 | AU8: 0 | AV8: 0 | AW8: 0 | AX8: 1 | AY8: 0 | AZ8: 1
A9: 1 | B9: APAC | C9: Japan | D9: R005 | E9: Nagoya Sakae | F9: Classic | G9: Apple Store+ | H9: Medium | I9: Slug | J9: 10' | K9: 15' | 18' | L9: 1 | M9: 0 | N9: 0 | O9: 0 | P9: 1 | Q9: 0 | R9: 1 | S9: 1 | T9: 1 | U9: 1 | V9: 0 | W9: 0 | X9: 1 | Y9: 1 | AA9: 1 | AB9: 0 | AC9: 1 | AD9: 1 | AE9: 0 | AF9: 0 | AG9: 0 | AH9: 0 | AI9: 0 | AJ9: 1 | AK9: 0 | AL9: 0 | AM9: 0 | AN9: 1 | AO9: 0 | AP9: 0 | AQ9: 0 | AR9: 1 | AS9: 0 | AT9: 1 | AU9: 0 | AV9: 1 | AW9: 1 | AX9: 0 | AY9: 0 | AZ9: 1 | BA9: 1
A10: 1 | B10: AMR | C10: USA | D10: R006 | E10: Lenox Square | F10: Vintage D | G10: Flagship | H10: X-Large | I10: Slug | J10: 12' | K10: - | L10: 1 | M10: 0 | N10: 1 | O10: 0 | P10: 0 | Q10: 0 | R10: 2 | S10: 1 | T10: 1 | U10: 1 | V10: 0 | W10: 2 | X10: 0 | Y10: 0 | Z10: 0 | AA10: 0 | AB10: 1 | AC10: 0 | AD10: 1 | AE10: 0 | AF10: 0 | AG10: 0 | AH10: 0 | AI10: 0 | AJ10: 2 | AK10: 0 | AL10: 1 | AM10: 0 | AN10: 0 | AO10: 0 | AP10: 0 | AQ10: 1 | AR10: 0 | AS10: 0 | AT10: 0 | AU10: 0 | AV10: 1 | AW10: 1 | AX10: 0 | AY10: 0 | AZ10: 1
A11: 1 | B11: AMR | C11: USA | D11: R007 | E11: Mall of America | F11: Vintage D | G11: Apple Store | H11: Medium | I11: Slug | J11: 12' | K11: - | L11: 0 | M11: 0 | N11: 1 | O11: 0 | P11: 0 | Q11: 0 | R11: 2 | S11: 1 | T11: 1 | U11: 0 | V11: 0 | W11: 1 | X11: 0 | Y11: 0 | Z11: 0 | AA11: 0 | AB11: 1 | AC11: 0 | AD11: 1 | AE11: 0 | AF11: 0 | AG11: 0 | AH11: 0 | AI11: 0 | AJ11: 1 | AK11: 0 | AL11: 0 | AM11: 0 | AN11: 0 | AO11: 0 | AP11: 0 | AQ11: 1 | AR11: 0 | AS11: 0 | AT11: 0 | AU11: 0 | AV11: 0 | AW11: 0 | AX11: 1 | AY11: 0 | AZ11: 1
A12: 1 | B12: AMR | C12: USA | D12: R009 | E12: Easton Town Center | F12: Vintage C | G12: Apple Store+ | H12: X-Large | I12: Slug | J12: 10' | K12: 15' | L12: 1 | M12: 0 | N12: 1 | O12: 0 | P12: 0 | Q12: 0 | R12: 1 | S12: 1 | T12: 1 | U12: 0 | V12: 0 | W12: 1 | X12: 1 | Y12: 0 | Z12: 1 | AA12: 1 | AB12: 1 | AC12: 0 | AD12: 1 | AE12: 0 | AF12: 0 | AG12: 0 | AH12: 0 | AI12: 0 | AJ12: 0 | AK12: 1 | AL12: 1 | AM12: 0 | AN12: 1 | AO12: 0 | AP12: 1 | AQ12: 0 | AR12: 0 | AS12: 1 | AT12: 0 | AU12: 0 | AV12: 1 | AW12: 1 | AX12: 0 | AY12: 0 | AZ12: 1
A13: 1 | B13: AMR | C13: USA | D13: R010 | E13: Tysons Corner | F13: Vintage D | G13: Apple Store | H13: Large | I13: Slot | J13: 10' | K13: - | L13: 1 | M13: 0 | N13: 0 | O13: 0 | P13: 0 | Q13: 1 | R13: 1 | S13: 1 | T13: 1 | U13: 0 | V13: 0 | W13: 1 | X13: 0 | Y13: 0 | Z13: 0 | AA13: 0 | AB13: 1 | AC13: 0 | AD13: 1 | AE13: 0 | AF13: 0 | AG13: 0 | AH13: 0 | AI13: 0 | AJ13: 1 | AK13: 0 | AL13: 0 | AM13: 0 | AN13: 0 | AO13: 0 | AP13: 0 | AQ13: 1 | AR13: 0 | AS13: 0 | AT13: 0 | AU13: 0 | AV13: 1 | AW13: 1 | AX13: 0 | AY13: 0 | AZ13: 1
A14: 1 | B14: AMR | C14: USA | D14: R011 | E14: MarketStreet Lynnfield | F14: Vintage D | G14: Apple Store+ | H14: Medium | I14: Slot | J14: 10' | K14: - | L14: 1 | M14: 0 | N14: 0 | O14: 0 | P14: 1 | Q14: 0 | R14: 1 | S14: 1 | T14: 1 | U14: 0 | V14: 0 | W14: 1 | X14: 0 | Y14: 0 | Z14: 0 | AA14: 0 | AB14: 1 | AC14: 0 | AD14: 1 | AE14: 0 | AF14: 0 | AG14: 0 | AH14: 0 | AI14: 0 | AJ14: 1 | AK14: 0 | AL14: 0 | AM14: 0 | AN14: 0 | AO14: 0 | AP14: 0 | AQ14: 1 | AR14: 0 | AS14: 0 | AT14: 0 | AU14: 0 | AV14: 1 | AW14: 1 | AX14: 0 | AY14: 0 | AZ14: 1
A15: 1 | B15: AMR | C15: USA | D15: R012 | E15: The Falls | F15: Vintage C | G15: Apple Store+ | H15: Medium | I15: Slot | J15: 10' | K15: 15' | L15: 1 | M15: 0 | N15: 0 | O15: 0 | P15: 1 | Q15: 0 | R15: 1 | S15: 1 | T15: 1 | U15: 0 | V15: 0 | W15: 0 | X15: 1 | Y15: 1 | Z15: 0 | AA15: 0 | AB15: 1 | AC15: 0 | AD15: 1 | AE15: 0 | AF15: 0 | AG15: 0 | AH15: 0 | AI15: 0 | AJ15: 0 | AK15: 1 | AL15: 0 | AM15: 0 | AN15: 1 | AO15: 0 | AP15: 1 | AQ15: 0 | AR15: 0 | AS15: 1 | AT15: 0 | AU15: 0 | AV15: 0 | AW15: 0 | AX15: 1 | AY15: 0 | AZ15: 1
A16: 1 | B16: AMR | C16: USA | D16: R013 | E16: Tice's Corner | F16: Vintage D | G16: Apple Store+ | H16: Medium | I16: Slot | J16: 8' | K16: - | L16: 1 | M16: 0 | N16: 0 | O16: 0 | P16: 1 | Q16: 0 | R16: 1 | S16: 1 | T16: 1 | U16: 0 | V16: 0 | W16: 1 | X16: 0 | Y16: 0 | Z16: 0 | AA16: 0 | AB16: 1 | AC16: 0 | AD16: 1 | AE16: 0 | AF16: 0 | AG16: 0 | AH16: 0 | AI16: 0 | AJ16: 1 | AK16: 0 | AL16: 0 | AM16: 0 | AN16: 0 | AO16: 1 | AP16: 0 | AQ16: 0 | AR16: 0 | AS16: 0 | AT16: 0 | AU16: 0 | AV16: 0 | AW16: 0 | AX16: 1 | AY16: 0 | AZ16: 1
A17: 1 | B17: AMR | C17: USA | D17: R014 | E17: Broadway Plaza (Walnut Creek) | F17: Vintage D | G17: Flagship | H17: Large | I17: Slug | J17: 10' | K17: - | L17: 1 | M17: 0 | N17: 1 | O17: 0 | P17: 0 | Q17: 0 | R17: 1 | S17: 1 | T17: 1 | U17: 0 | V17: 0 | W17: 1 | X17: 0 | Y17: 0 | Z17: 0 | AA17: 0 | AB17: 1 | AC17: 0 | AD17: 1 | AE17: 0 | AF17: 0 | AG17: 0 | AH17: 0 | AI17: 0 | AJ17: 1 | AK17: 0 | AL17: 0 | AM17: 0 | AN17: 0 | AO17: 0 | AP17: 0 | AQ17: 1 | AR17: 0 | AS17: 0 | AT17: 0 | AU17: 0 | AV17: 1 | AW17: 1 | AX17: 0 | AY17: 0 | AZ17: 1
A18: 1 | B18: AMR | C18: USA | D18: R015 | E18: Fashion Island | F18: Vintage C | G18: Apple Store+ | H18: X-Large | I18: Slot | J18: 10' | K18: 15' | L18: 1 | M18: 0 | N18: 1 | O18: 0 | P18: 0 | Q18: 0 | R18: 1 | S18: 1 | T18: 1 | U18: 1 | V18: 0 | W18: 0 | X18: 1 | Y18: 1 | Z18: 0 | AA18: 1 | AB18: 0 | AC18: 1 | AD18: 1 | AE18: 1 | AF18: 0 | AG18: 0 | AH18: 0 | AI18: 0 | AJ18: 0 | AK18: 1 | AL18: 1 | AM18: 0 | AN18: 2 | AO18: 1 | AP18: 0 | AQ18: 0 | AR18: 0 | AS18: 1 | AT18: 0 | AU18: 0 | AV18: 1 | AW18: 1 | AX18: 0 | AY18: 0 | AZ18: 1
A19: 1 | B19: AMR | C19: USA | D19: R016 | E19: Walden Galleria | F19: Vintage D | G19: Apple Store | H19: Medium | I19: Slot | J19: 10' | K19: - | L19: 1 | M19: 0 | N19: 0 | O19: 0 | P19: 1 | Q19: 0 | R19: 1 | S19: 1 | T19: 1 | U19: 0 | V19: 0 | W19: 1 | X19: 0 | Y19: 0 | Z19: 0 | AA19: 0 | AB19: 1 | AC19: 0 | AD19: 1 | AE19: 0 | AF19: 0 | AG19: 0 | AH19: 0 | AI19: 0 | AJ19: 1 | AK19: 0 | AL19: 0 | AM19: 0 | AN19: 0 | AO19: 1 | AP19: 0 | AQ19: 0 | AR19: 0 | AS19: 0 | AT19: 0 | AU19: 0 | AV19: 0 | AW19: 0 | AX19: 1 | AY19: 0 | AZ19: 1
A20: 1 | B20: AMR | C20: USA | D20: R017 | E20: Crossgates | F20: Vintage D | G20: Apple Store | H20: Medium | I20: Slot | J20: 10' | K20: - | L20: 1 | M20: 0 | N20: 0 | O20: 0 | P20: 1 | Q20: 0 | R20: 1 | S20: 1 | T20: 1 | U20: 0 | V20: 0 | W20: 1 | X20: 0 | Y20: 0 | Z20: 0 | AA20: 0 | AB20: 1 | AC20: 0 | AD20: 1 | AE20: 0 | AF20: 0 | AG20: 0 | AH20: 0 | AI20: 0 | AJ20: 1 | AK20: 0 | AL20: 0 | AM20: 0 | AN20: 0 | AO20: 0 | AP20: 0 | AQ20: 1 | AR20: 0 | AS20: 0 | AT20: 0 | AU20: 0 | AV20: 1 | AW20: 1 | AX20: 0 | AY20: 0 | AZ20: 1
A21: 1 | B21: AMR | C21: USA | D21: R018 | E21: Woodfield | F21: Vintage D | G21: Apple Store | H21: Medium | I21: Slot | J21: 10' | K21: - | L21: 1 | M21: 0 | N21: 0 | O21: 0 | P21: 1 | Q21: 0 | R21: 1 | S21: 1 | T21: 1 | U21: 0 | V21: 0 | W21: 1 | X21: 0 | Y21: 0 | Z21: 0 | AA21: 0 | AB21: 1 | AC21: 0 | AD21: 1 | AE21: 0 | AF21: 0 | AG21: 0 | AH21: 0 | AI21: 0 | AJ21: 1 | AK21: 0 | AL21: 0 | AM21: 0 | AN21: 0 | AO21: 0 | AP21: 0 | AQ21: 1 | AR21: 0 | AS21: 0 | AT21: 0 | AU21: 0 | AV21: 1 | AW21: 1 | AX21: 0 | AY21: 0 | AZ21: 1
... A44: 1 | B44: AMR | C44: USA | D44: R043 | E44: Short Hills | F44: Vintage C | G44: Apple Store | H44: X-Large | I44: Slot | J44: 10' | K44: 15' | L44: 1 | M44: 0 | N44: 0 | O44: 1 | P44: 0 | Q44: 0 | R44: 1 | S44: 1 | T44: 1 | U44: 1 | V44: 0 | W44: 1 | X44: 1 | Y44: 0 | Z44: 1 | AA44: 1 | AB44: 0 | AC44: 1 | AD44: 1 | AE44: 0 | AF44: 0 | AG44: 1 | AH44: 1 | AI44: 0 | AJ44: 0 | AK44: 0 | AL44: 0 | AM44: 0 | AN44: 0 | AO44: 0 | AP44: 1 | AQ44: 0 | AR44: 0 | AS44: 1 | AT44: 0 | AU44: 0 | AV44: 1 | AW44: 1 | AX44: 0 | AY44: 0 | AZ44: 1
A45: 1 | B45: AMR | C45: USA | D45: R044 | E45: Montgomery Village *new name* | F45: Vintage E | G45: Apple Store | H45: Small | I45: Slot | J45: 8' | 10' | L45: 0 | M45: 0 | N45: 0 | O45: 0 | P45: 1 | Q45: 0 | R45: 1 | S45: 1 | T45: 1 | U45: 0 | V45: 0 | W45: 1 | X45: 0 | Y45: 0 | Z45: 0 | AA45: 0 | AB45: 1 | AC45: 0 | AD45: 1 | AE45: 0 | AF45: 0 | AG45: 0 | AH45: 0 | AI45: 0 | AJ45: 1 | AK45: 0 | AL45: 0 | AM45: 0 | AN45: 0 | AO45: 0 | AP45: 0 | AQ45: 1 | AR45: 0 | AS45: 0 | AT45: 0 | AU45: 0 | AV45: 0 | AW45: 0 | AX45: 0 | AY45: 1 | AZ45: 0
A46: 1 | B46: EMEIA | C46: DE | D46: R045 | E46: ROSENSTRASSE | F46: Vintage C | G46: Apple Store+ | H46: X-Large | I46: Slot | J46: 8' | K46: 15' | L46: 1 | M46: 0 | N46: 1 | O46: 0 | P46: 0 | Q46: 0 | R46: 1 | S46: 1 | T46: 1 | U46: 1 | V46: 0 | W46: 1 | X46: 1 | Y46: 1 | AA46: 1 | AB46: 0 | AC46: 1 | AD46: 1 | AE46: 0 | AF46: 1 | AG46: 0 | AH46: 0 | AI46: 1 | AJ46: 0 | AK46: 0 | AL46: 0 | AM46: 0 | AN46: 1 | AO46: 1 | AP46: 0 | AQ46: 0 | AR46: 0 | AS46: 1 | AT46: 0 | AU46: 1 | AV46: 1 | AW46: 1 | AX46: 0 | AY46: 0 | AZ46: 1
A47: 1 | B47: AMR | C47: USA | D47: R046 | E47: Nanuet (Palisades) | F47: Vintage C | G47: Apple Store+ | H47: Large | I47: Slot | J47: 10' | K47: 15' | L47: 0 | M47: 1 | N47: 0 | O47: 0 | P47: 1 | Q47: 0 | R47: 1 | S47: 1 | T47: 1 | U47: 1 | V47: 0 | W47: 1 | X47: 1 | Y47: 0 | Z47: 1 | AA47: 1 | AB47: 1 | AC47: 0 | AD47: 1 | AE47: 0 | AF47: 0 | AG47: 0 | AH47: 0 | AI47: 0 | AJ47: 0 | AK47: 1 | AL47: 0 | AM47: 0 | AN47: 1 | AO47: 0 | AP47: 1 | AQ47: 0 | AR47: 0 | AS47: 1 | AT47: 0 | AU47: 0 | AV47: 1 | AW47: 1 | AX47: 0 | AY47: 0 | AZ47: 1
A48: 1 | B48: AMR | C48: USA | D48: R047 | E48: Cherry Creek | F48: Vintage D | G48: Apple Store | H48: Medium | I48: Slug | J48: 12' | 20' | K48: - | L48: 1 | M48: 0 | N48: 1 | O48: 0 | P48: 0 | Q48: 0 | R48: 2 | S48: 1 | T48: 2 | U48: 0 | V48: 0 | W48: 1 | X48: 0 | Y48: 0 | Z48: 0 | AA48: 0 | AB48: 1 | AC48: 0 | AD48: 1 | AE48: 0 | AF48: 0 | AG48: 0 | AH48: 0 | AI48: 0 | AJ48: 1 | AK48: 0 | AL48: 0 | AM48: 0 | AN48: 0 | AO48: 1 | AP48: 0 | AQ48: 0 | AR48: 0 | AS48: 0 | AT48: 0 | AU48: 0 | AV48: 1 | AW48: 1 | AX48: 0 | AY48: 0 | AZ48: 1
A49: 1 | B49: APAC | C49: Japan | D49: R048 | E49: Fukuoka Tenjin | F49: Vintage D | G49: Flagship | H49: Medium | I49: Slug | J49: 8' | K49: - | L49: 1 | M49: 0 | N49: 1 | O49: 0 | P49: 0 | Q49: 0 | R49: 1 | S49: 1 | T49: 1 | U49: 1 | V49: 0 | W49: 1 | X49: 0 | Y49: 0 | AA49: 0 | AB49: 1 | AC49: 0 | AD49: 1 | AE49: 0 | AF49: 0 | AG49: 0 | AH49: 0 | AI49: 0 | AJ49: 1 | AK49: 0 | AL49: 0 | AM49: 0 | AN49: 0 | AO49: 0 | AP49: 0 | AQ49: 0 | AR49: 1 | AS49: 0 | AT49: 0 | AU49: 0 | AV49: 1 | AW49: 1 | AX49: 0 | AY49: 0 | AZ49: 1 | BA49: 1
A50: 1 | B50: AMR | C50: USA | D50: R049 | E50: Southpoint | F50: Vintage D | G50: Apple Store+ | H50: Large | I50: Slug | J50: 12' | K50: - | L50: 0 | M50: 0 | N50: 1 | O50: 0 | P50: 0 | Q50: 0 | R50: 2 | S50: 1 | T50: 1 | U50: 0 | V50: 0 | W50: 1 | X50: 0 | Y50: 0 | Z50: 0 | AA50: 0 | AB50: 1 | AC50: 0 | AD50: 1 | AE50: 0 | AF50: 0 | AG50: 0 | AH50: 0 | AI50: 0 | AJ50: 1 | AK50: 0 | AL50: 0 | AM50: 0 | AN50: 0 | AO50: 0 | AP50: 0 | AQ50: 1 | AR50: 0 | AS50: 0 | AT50: 0 | AU50: 0 | AV50: 0 | AW50: 0 | AX50: 1 | AY50: 0 | AZ50: 1
A51: 1 | B51: AMR | C51: USA | D51: R050 | E51: The Grove | F51: Vintage D | G51: Flagship | H51: Large | I51: Slot | J51: 12' | K51: - | L51: 1 | M51: 0 | N51: 1 | O51: 0 | P51: 0 | Q51: 0 | R51: 2 | S51: 1 | T51: 1 | U51: 0 | V51: 0 | W51: 1 | X51: 0 | Y51: 0 | Z51: 0 | AA51: 0 | AB51: 1 | AC51: 0 | AD51: 1 | AE51: 0 | AF51: 0 | AG51: 0 | AH51: 0 | AI51: 0 | AJ51: 1 | AK51: 0 | AL51: 0 | AM51: 0 | AN51: 0 | AO51: 0 | AP51: 0 | AQ51: 1 | AR51: 0 | AS51: 0 | AT51: 0 | AU51: 0 | AV51: 1 | AW51: 1 | AX51: 0 | AY51: 0 | AZ51: 1
A52: 1 | B52: AMR | C52: USA | D52: R051 | E52: Third Street Promenade | F52: Vintage D | G52: Flagship | H52: Medium | I52: Slug | J52: 20' | K52: - | L52: 2 | M52: 0 | N52: 1 | O52: 0 | P52: 0 | Q52: 0 | R52: 1 | S52: 1 | T52: 4 | U52: 1 | V52: 0 | W52: 1 | X52: 0 | Y52: 0 | Z52: 0 | AA52: 1 | AB52: 1 | AC52: 0 | AD52: 1 | AE52: 0 | AF52: 1 | AG52: 0 | AH52: 1 | AI52: 0 | AJ52: 0 | AK52: 0 | AL52: 1 | AM52: 1 | AN52: 0 | AO52: 1 | AP52: 0 | AQ52: 0 | AR52: 0 | AS52: 0 | AT52: 0 | AU52: 0 | AV52: 1 | AW52: 1 | AX52: 0 | AY52: 0 | AZ52: 1
A53: 1 | B53: AMR | C53: USA | D53: R053 | E53: Millenia | F53: Vintage C | G53: Apple Store | H53: X-Large | I53: Slot | J53: 10' | K53: 15' | L53: 2 | M53: 0 | N53: 1 | O53: 0 | P53: 0 | Q53: 0 | R53: 1 | S53: 1 | T53: 1 | U53: 1 | V53: 0 | W53: 1 | X53: 1 | Y53: 0 | Z53: 0 | AA53: 1 | AB53: 0 | AC53: 1 | AD53: 2 | AE53: 0 | AF53: 0 | AG53: 1 | AH53: 1 | AI53: 0 | AJ53: 0 | AK53: 0 | AL53: 0 | AM53: 0 | AN53: 1 | AO53: 0 | AP53: 1 | AQ53: 0 | AR53: 0 | AS53: 1 | AT53: 0 | AU53: 0 | AV53: 1 | AW53: 1 | AX53: 0 | AY53: 0 | AZ53: 1
A54: 1 | B54: AMR | C54: USA | D54: R054 | E54: Southdale | F54: Vintage C | G54: Apple Store | H54: X-Large | I54: Slug | J54: 10' | K54: 15' | L54: 1 | M54: 0 | N54: 1 | O54: 0 | P54: 0 | Q54: 0 | R54: 1 | S54: 1 | T54: 1 | U54: 1 | V54: 0 | W54: 0 | X54: 1 | Y54: 1 | Z54: 0 | AA54: 1 | AB54: 1 | AC54: 0 | AD54: 1 | AE54: 0 | AF54: 0 | AG54: 0 | AH54: 0 | AI54: 0 | AJ54: 0 | AK54: 1 | AL54: 1 | AM54: 0 | AN54: 1 | AO54: 0 | AP54: 1 | AQ54: 0 | AR54: 0 | AS54: 1 | AT54: 0 | AU54: 0 | AV54: 1 | AW54: 1 | AX54: 0 | AY54: 0 | AZ54: 1
A55: 1 | B55: AMR | C55: USA | D55: R055 | E55: Somerset | F55: Vintage C | G55: Apple Store | H55: Large | I55: Slot | J55: 10' | K55: 15' | L55: 1 | M55: 0 | N55: 0 | O55: 1 | P55: 0 | Q55: 0 | R55: 1 | S55: 1 | T55: 1 | U55: 0 | V55: 0 | W55: 1 | X55: 1 | Y55: 0 | Z55: 1 | AA55: 0 | AB55: 1 | AC55: 0 | AD55: 1 | AE55: 0 | AF55: 0 | AG55: 0 | AH55: 0 | AI55: 0 | AJ55: 0 | AK55: 1 | AL55: 0 | AM55: 0 | AN55: 0 | AO55: 0 | AP55: 1 | AQ55: 0 | AR55: 0 | AS55: 1 | AT55: 0 | AU55: 0 | AV55: 1 | AW55: 1 | AX55: 0 | AY55: 0 | AZ55: 1
A56: 1 | B56: AMR | C56: USA | D56: R056 | E56: Oakbrook | F56: Vintage C | G56: Apple Store+ | H56: X-Large | I56: Slug | J56: 8' | K56: 15' | L56: 0 | M56: 1 | N56: 1 | O56: 0 | P56: 0 | Q56: 0 | R56: 1 | S56: 1 | T56: 1 | U56: 1 | V56: 0 | W56: 1 | X56: 1 | Y56: 0 | Z56: 1 | AA56: 1 | AB56: 1 | AC56: 0 | AD56: 1 | AE56: 0 | AF56: 0 | AG56: 0 | AH56: 0 | AI56: 0 | AJ56: 0 | AK56: 1 | AL56: 1 | AM56: 0 | AN56: 0 | AO56: 0 | AP56: 1 | AQ56: 0 | AR56: 0 | AS56: 1 | AT56: 0 | AU56: 0 | AV56: 1 | AW56: 1 | AX56: 0 | AY56: 0 | AZ56: 1
A57: 1 | B57: AMR | C57: USA | D57: R057 | E57: Bay Street | F57: Vintage D | G57: Apple Store+ | H57: Large | I57: Slot | J57: 10' | K57: - | L57: 1 | M57: 0 | N57: 0 | O57: 0 | P57: 1 | Q57: 0 | R57: 1 | S57: 1 | T57: 1 | U57: 1 | V57: 0 | W57: 1 | X57: 0 | Y57: 0 | Z57: 0 | AA57: 0 | AB57: 1 | AC57: 0 | AD57: 1 | AE57: 0 | AF57: 0 | AG57: 0 | AH57: 0 | AI57: 0 | AJ57: 1 | AK57: 0 | AL57: 0 | AM57: 0 | AN57: 0 | AO57: 1 | AP57: 0 | AQ57: 0 | AR57: 0 | AS57: 0 | AT57: 0 | AU57: 0 | AV57: 1 | AW57: 1 | AX57: 0 | AY57: 0 | AZ57: 1
A58: 1 | B58: AMR | C58: USA | D58: R058 | E58: Houston Galleria | F58: Vintage C | G58: Apple Store | H58: X-Large | I58: Slug | J58: 8' | K58: 15' | L58: 1 | M58: 0 | N58: 1 | O58: 0 | P58: 0 | Q58: 0 | R58: 1 | S58: 1 | T58: 1 | U58: 1 | V58: 0 | W58: 1 | X58: 2 | Y58: 0 | Z58: 1 | AA58: 1 | AB58: 1 | AC58: 0 | AD58: 2 | AE58: 0 | AF58: 0 | AG58: 1 | AH58: 1 | AI58: 0 | AJ58: 0 | AK58: 0 | AL58: 0 | AM58: 0 | AN58: 1 | AO58: 1 | AP58: 0 | AQ58: 0 | AR58: 0 | AS58: 1 | AT58: 0 | AU58: 0 | AV58: 1 | AW58: 1 | AX58: 0 | AY58: 0 | AZ58: 1
A59: 1 | B59: AMR | C59: USA | D59: R059 | E59: Mayfair | F59: Vintage D | G59: Apple Store | H59: Medium | I59: Slot | J59: 8' | K59: - | L59: 0 | M59: 0 | N59: 0 | O59: 0 | P59: 1 | Q59: 0 | R59: 1 | S59: 1 | T59: 1 | U59: 0 | V59: 0 | W59: 1 | X59: 0 | Y59: 0 | Z59: 0 | AA59: 0 | AB59: 1 | AC59: 0 | AD59: 1 | AE59: 0 | AF59: 0 | AG59: 0 | AH59: 0 | AI59: 0 | AJ59: 1 | AK59: 0 | AL59: 0 | AM59: 0 | AN59: 0 | AO59: 1 | AP59: 0 | AQ59: 0 | AR59: 0 | AS59: 0 | AT59: 0 | AU59: 0 | AV59: 0 | AW59: 0 | AX59: 1 | AY59: 0 | AZ59: 1
A60: 1 | B60: AMR | C60: USA | D60: R060 | E60: Roosevelt Field | F60: Vintage E | G60: Apple Store | H60: Large | I60: Slot | J60: 8' | L60: 1 | M60: 0 | N60: 0 | O60: 0 | P60: 0 | Q60: 1 | R60: 1 | S60: 1 | T60: 2 | U60: 1 | V60: 0 | W60: 1 | X60: 0 | Y60: 0 | Z60: 0 | AA60: 1 | AB60: 1 | AC60: 0 | AD60: 1 | AE60: 0 | AF60: 0 | AG60: 0 | AH60: 0 | AI60: 0 | AJ60: 1 | AK60: 0 | AL60: 1 | AM60: 0 | AN60: 0 | AO60: 1 | AP60: 0 | AQ60: 0 | AR60: 0 | AS60: 0 | AT60: 0 | AU60: 0 | AV60: 1 | AW60: 1 | AX60: 0 | AY60: 0 | AZ60: 1
A61: 1 | B61: AMR | C61: USA | D61: R061 | E61: The Westchester | F61: Vintage D | G61: Apple Store | H61: Medium | I61: Slug | J61: 10' | K61: - | L61: 1 | M61: 0 | N61: 0 | O61: 0 | P61: 1 | Q61: 0 | R61: 1 | S61: 1 | T61: 1 | U61: 0 | V61: 0 | W61: 1 | X61: 0 | Y61: 0 | Z61: 0 | AA61: 0 | AB61: 1 | AC61: 0 | AD61: 1 | AE61: 0 | AF61: 0 | AG61: 0 | AH61: 0 | AI61: 0 | AJ61: 1 | AK61: 0 | AL61: 0 | AM61: 0 | AN61: 0 | AO61: 1 | AP61: 0 | AQ61: 0 | AR61: 0 | AS61: 0 | AT61: 0 | AU61: 0 | AV61: 0 | AW61: 0 | AX61: 1 | AY61: 0 | AZ61: 1
A62: 1 | B62: AMR | C62: USA | D62: R062 | E62: West County | F62: Vintage D | G62: Apple Store | H62: Medium | I62: Slot | J62: 10' | K62: - | L62: 0 | M62: 0 | N62: 1 | O62: 0 | P62: 0 | Q62: 0 | R62: 1 | S62: 1 | T62: 1 | U62: 0 | V62: 0 | W62: 1 | X62: 0 | Y62: 0 | Z62: 0 | AA62: 0 | AB62: 1 | AC62: 0 | AD62: 1 | AE62: 0 | AF62: 0 | AG62: 0 | AH62: 0 | AI62: 0 | AJ62: 1 | AK62: 0 | AL62: 0 | AM62: 0 | AN62: 0 | AO62: 0 | AP62: 0 | AQ62: 1 | AR62: 0 | AS62: 0 | AT62: 0 | AU62: 0 | AV62: 0 | AW62: 0 | AX62: 1 | AY62: 0 | AZ62: 1
A63: 1 | B63: AMR | C63: USA | D63: R063 | E63: Towson Town Center | F63: Vintage C | G63: Apple Store | H63: X-Large | I63: Slot | J63: 10' | K63: 15' | L63: 1 | M63: 0 | N63: 1 | O63: 0 | P63: 0 | Q63: 0 | R63: 1 | S63: 1 | T63: 1 | U63: 0 | V63: 0 | W63: 1 | X63: 1 | Y63: 0 | Z63: 0 | AA63: 1 | AB63: 0 | AC63: 1 | AD63: 1 | AE63: 0 | AF63: 0 | AG63: 0 | AH63: 0 | AI63: 0 | AJ63: 1 | AK63: 0 | AL63: 1 | AM63: 0 | AN63: 0 | AO63: 0 | AP63: 1 | AQ63: 0 | AR63: 0 | AS63: 1 | AT63: 0 | AU63: 0 | AV63: 1 | AW63: 1 | AX63: 0 | AY63: 0 | AZ63: 1
...

Sheet Avenue Assignments
N1: Confirmed with Tyler - no iPhones | R1: Confirmed with Geo (check 'Geo Accy Fixture' column at end) | S1: Confirmed with Geo (check 'Geo Accy Fixture' column at end) | U1: Confirmed with Geo (check 'Geo Accy Fixture' column at end) | BG1: V159 x1 Pink -Flex bay only | BI1: 1x needed per 10', x2 for 15', **have to add model in drawer** | BL1: x0 | BM1: x1 | CG1: Input manually using Geo inputs | CK1: Input manually using Geo inputs | CO1: Input manually using Geo inputs | CS1: 7/24 - aligned with Lisa to remove (email from Sabrina)
G2: 278 | H2: 278 | I2: 0 | J2: 0
A3: Store Number | B3: Store Name | C3: City | D3: Country or Region | E3: Geo | F3: Footprint | G3: 278 | H3: V159 - Pink | I3: V159 - Black | J3: V159 - White | K3: Demo Space | L3: FB1 (Tyler) | M3: FB2 (Julie) | N3: FB3 (Tyler) | O3: FB4 (Lisa) | P3: FB5 (Tyler) | Q3: FB6 (Eric) | R3: Express Wall | S3: ACCESSORIES FIXTURE-ACRONYM | T3: ACCESSORIES FIXTURE | U3: ACCESSORIES TABLE-ACRONYM | V3: ACCESSORIES TABLE | W3: AIRPODS-ACRONYM | X3: AIRPODS | Y3: AIRTAG-ACRONYM | Z3: AIRTAG | AA3: APP ENABLED ACCESSORIES-ACRONYM | AB3: APP ENABLED ACCESSORIES | AC3: APPLE MUSIC-ACRONYM | AD3: APPLE MUSIC | AE3: APPLE TV PLUS-ACRONYM | AF3: APPLE TV PLUS | AG3: APPLE VISION PRO-ACRONYM | AH3: APPLE VISION PRO | AI3: APU-ACRONYM | AJ3: APU | AK3: ARCADE-ACRONYM | AL3: ARCADE | AM3: CONNECTED HOME-ACRONYM | AN3: CONNECTED HOME | AO3: ESSENTIALS-ACRONYM | AP3: ESSENTIALS | AQ3: EXPRESS/PRODUCT ZONE-ACRONYM | AR3: EXPRESS/PRODUCT ZONE | AS3: FEATURE BAY-ACRONYM | AT3: FEATURE BAY | AU3: FITNESS PLUS-ACRONYM | AV3: FITNESS PLUS | AW3: GAMING-ACRONYM | AX3: GAMING | AY3: GRAPHIC PANEL | LIVING WALL-ACRONYM | AZ3: GRAPHIC PANEL | LIVING WALL | BA3: HOME-ACRONYM | BB3: HOME | BC3: IPAD CASES/MAC BAGS-ACRONYM | BD3: IPAD CASES/MAC BAGS | BE3: IPAD HERO-ACRONYM | BF3: IPAD HERO | BG3: IPHONE CASES-ACRONYM | BH3: IPHONE CASES | BI3: V159 - Pink | BJ3: IPHONE FEATURES-ACRONYM | BK3: IPHONE FEATURES | BL3: V159 - Pink | BM3: V159-White | BN3: IPHONE HERO-ACRONYM | BO3: IPHONE HERO | BP3: LOGO-ACRONYM | BQ3: LOGO | BR3: MAC HERO-ACRONYM | BS3: MAC HERO | BT3: MUSIC-ACRONYM | BU3: MUSIC | BV3: NSD MUSIC DEMO-ACRONYM | BW3: NSD MUSIC DEMO | BX3: SOFTGOODS-ACRONYM | BY3: SOFTGOODS | BZ3: WATCH-ACRONYM | CA3: WATCH | CB3: WATCH HERO-ACRONYM | CC3: WATCH HERO | CD3: IPHONE AND MAC ACCESSORIES (VIN D CONVERSION) | CE3: IPHONE ACCESSORIES (VIN D CONVERSION) | CF3: WW Counts | CG3: AMR ACCY FIXTURES | CH3: V159 - Pink | CI3: V159 - Black | CJ3: V159 - White | CK3: APAC ACCY FIXTURES | CL3: V159 - Pink | CM3: V159 - Black | CN3: V159 - White | CO3: EMEIA ACCY FIXTURES | CP3: V159 - Pink | CQ3: V159 - Black | CR3: V159 - White | CS3: iPhone Header | CT3: V159 - Pink | CU3: V159 - Black | CV3: V159 - White
A4: R001 | B4: GLEV53 Color BLE GALLERIA | C4: GLEV53 Color BLE,CA | D4: US | E4: AMR | F4: US | 2.16W (2.10W 2.6W) | R000 GLEV53 Color BLE GALLERIA | G4: Vintage | H4: 0 | I4: 0 | J4: 0 | K4: 1,2,3,4,5,6 | L4: X | M4: X | N4: X | O4: X | P4: X | Q4: X | AA4: AEA_FB3_2W_MF X 1 | AB4: R_US_AEA_FB3_2W | AO4: ESSENTIALS_2W_FB5_2W X 1 | AP4: R_US_ESSENTIALS_2W_FB5_2W | AS4: FB4 X 1 | AT4: R_US_FB4 | BG4: 6W | BH4: R_US_IPHONE_FB6_4W_FB2_2W | BT4: MUSIC_2W_FB1_2W X 1 | BU4: R_US_MUSIC_2W_FB1_2W | BX4: R_US_IPAD_2W X 1+R_US_MAC_1W X 1 | BY4: R_US_IPAD_2W+R_US_MAC_1W | BZ4: WATCH_1W X 1 | CA4: R_US_WATCH_1W | CG4: 0 | CH4: 0 | CI4: 0 | CJ4: 0 | CK4: 0 | CL4: 0 | CM4: 0 | CN4: 0 | CO4: 0 | CP4: 0 | CQ4: 0 | CR4: 0 | CS4: 0 | CT4: 0 | CU4: 0 | CV4: 0
A5: R002 | B5: PALO ALTO | C5: PALO ALTO,CA | D5: US | E5: AMR | F5: US | 200' (2x100') | NSD 2.0 | R002 | Palo Alto | G5: Avenues | H5: 1 | I5: 0 | J5: 0 | K5: N/A | W5: US_AIRPODS_10FT X 1 | X5: US_AIRPODS_10FT | Y5: AIRTAG_10FT X 1 | Z5: US_AIRTAG_10FT | AC5: APPLE_MUSIC_10FT X 1 | AD5: US_APPLE_MUSIC_10FT | AE5: TV_PLUS_10FT_FLEX X 1 | AF5: US_TV_PLUS_10FT_FLEX | AK5: ARCADE_15FT X 1 | AL5: US_ARCADE_15FT | AM5: CONNECTED_HOME_10FT X 1 | AN5: US_CONNECTED_HOME_10FT | AO5: ESSENTIALS_15FT X 1 | AP5: US_ESSENTIALS_15FT | AU5: FITNESS_PLUS_10FT X 1 | AV5: US_FITNESS_PLUS_10FT | AY5: LIVING_WALL_25FT X 2+US_GRAPHIC_PANEL_10FT X 2 | AZ5: US_LIVING_WALL_25FT+US_LIVING_WALL_25FT+US_GRAPHIC_PANEL_10FT+US_GRAPHIC_PANEL_10FT | BG5: 10FT (D.1) | BH5: US_IPHONE_10FT | BJ5: IPHONE_FEATURES_10FT X 1 | BK5: US_IPHONE_FEATURES_10FT | BL5: 1 | BM5: 0 | BX5: SOFTGOODS_10FT X 1 | BY5: US_SOFTGOODS_10FT | BZ5: US_WATCH_EXTENDED_10FT X 1 | CA5: US_WATCH_EXTENDED_10FT | CD5: 1 | CE5: 1 | CG5: 0 | CH5: 0 | CI5: 0 | CJ5: 0 | CK5: 0 | CL5: 0 | CM5: 0 | CN5: 0 | CO5: 0 | CP5: 0 | CQ5: 0 | CR5: 0 | CS5: 0 | CT5: 0 | CU5: 0 | CV5: 0
A6: R003 | B6: BELLEVUE SQUARE | C6: BELLEVUE,WA | D6: US | E6: AMR | F6: US | 3.12W (6.6W) | R003 | Bellevue Square | G6: Vintage | H6: 0 | I6: 0 | J6: 0 | K6: 1,2,3,4,5,6 | L6: X | M6: X | N6: X | O6: X | P6: X | Q6: X | AA6: AEA_2W_FB3_2W X 1 | AB6: R_US_AEA_2W_FB3_2W | AO6: ESSENTIALS_2W_FB5_2W X 1 | AP6: R_US_ESSENTIALS_2W_FB5_2W | AS6: FB4 X 1 | AT6: R_US_FB4 | BG6: 6W | BH6: R_US_IPHONE_4W_FB2_2W | BT6: MUSIC_2W_FB1_2W X 1 | BU6: R_US_MUSIC_2W_FB1_2W | BX6: SOFTGOODS_2W_FB6_2W X 1 | BY6: R_US_SOFTGOODS_2W_FB6_2W | BZ6: R_US_WATCH_2W X 1 | CA6: R_US_WATCH_2W | CG6: 0 | CH6: 0 | CI6: 0 | CJ6: 0 | CK6: 0 | CL6: 0 | CM6: 0 | CN6: 0 | CO6: 0 | CP6: 0 | CQ6: 0 | CR6: 0 | CS6: 0 | CT6: 0 | CU6: 0 | CV6: 0
A7: R004 | B7: SOUTH COAST PLAZA | C7: COSTA MESA,CA | D7: US | E7: AMR | F7: US | 2.12W (4.6W) | G7: Vintage | H7: 0 | I7: 0 | J7: 0 | K7: 1,2,3,4 | L7: X | M7: X | N7: X | O7: X | AA7: AEA_FB3_2W X 1 | AB7: R_US_AEA_FB3_2W | AO7: ESSENTIALS_4W X 1 | AP7: R_US_ESSENTIALS_4W | AS7: FB4 X 1 | AT7: R_US_FB4 | BG7: 4W | BH7: R_US_IPHONE_2W_FB2_2W | BT7: MUSIC_2W_FB1 X 1 | BU7: R_US_MUSIC_2W_FB1 | BX7: R_US_IPAD_2W X 1+R_US_MAC_1W X 1 | BY7: R_US_IPAD_2W+R_US_MAC_1W | BZ7: WATCH_1W X 1 | CA7: R_US_WATCH_1W | CG7: 0 | CH7: 0 | CI7: 0 | CJ7: 0 | CK7: 0 | CL7: 0 | CM7: 0 | CN7: 0 | CO7: 0 | CP7: 0 | CQ7: 0 | CR7: 0 | CS7: 0 | CT7: 0 | CU7: 0 | CV7: 0
A8: R005 | B8: NAGOYA SAKAE | C8: NAKA-KU NAGOYA,23 | D8: JP | E8: APAC | F8: JP | 36W (2.18W) | VIN C | R005 NAGOYA SAKAE | G8: Vintage | H8: 0 | I8: 0 | J8: 0 | K8: 1,1,2,3,4,5,6 | L8: X | M8: X | N8: X | O8: X | P8: X | Q8: X | AA8: AEA_2W_FB3 X 1 | AB8: R_JP_AEA_2W_FB3_SHORT | AO8: ESSENTIALS_4W_FB5_2W X 1 | AP8: R_JP_ESSENTIALS_4W_FB5_2W_SHORT | AS8: FB4 X 1 | AT8: R_JP_FB4 | BG8: 8W | BH8: R_JP_IPHONE_4W_FB2_2W_SHORT | BT8: MUSIC_2W_FB1_2W X 1 | BU8: R_JP_MUSIC_2W_FB1_2W_SHORT | BX8: SOFTGOODS_2W_FB6_2W X 1 | BY8: R_JP_SOFTGOODS_2W_FB6_2W_SHORT | BZ8: WATCH_2W X 1 | CA8: R_JP_WATCH_2W_SHORT | CG8: 0 | CH8: 0 | CI8: 0 | CJ8: 0 | CK8: 0 | CL8: 0 | CM8: 0 | CN8: 0 | CO8: 0 | CP8: 0 | CQ8: 0 | CR8: 0 | CS8: 0 | CT8: 0 | CU8: 0 | CV8: 0
A9: R006 | B9: LENOX SQUARE | C9: ATLANTA,GA | D9: US | E9: AMR | F9: US | 120’ (1x70 1x40 1x30) | NSD 2.0 | 2F | R006 | Lenox Squ | G9: Avenues | H9: 1 | I9: 0 | J9: 0 | K9: N/A | W9: US_AIRPODS_10FT X 1 | X9: US_AIRPODS_10FT | Y9: AIRTAG_10FT X 1 | Z9: US_AIRTAG_10FT | AC9: APPLE_MUSIC_10FT X 1 | AD9: US_APPLE_MUSIC_10FT | AE9: TV_PLUS_10FT_FLEX_LP X 1 | AF9: US_TV_PLUS_10FT_FLEX_LP | AK9: ARCADE_10FT X 1 | AL9: US_ARCADE_10FT | AM9: CONNECTED_HOME_10FT X 1 | AN9: US_CONNECTED_HOME_10FT | AO9: ESSENTIALS_10FT_FLEXBAY X 1+US_ESSENTIALS_10FT_MULTI_CL X 1 | AP9: US_ESSENTIALS_10FT_FLEXBAY+US_ESSENTIALS_10FT_MULTI_CL | AU9: FITNESS_PLUS_10FT X 1 | AV9: US_FITNESS_PLUS_10FT | BG9: 20FT (D.1) | BH9: US_IPHONE_10FT+US_IPHONE_10FT | BJ9: IPHONE_FEATURES_10FT X 1 | BK9: US_IPHONE_FEATURES_10FT | BL9: 1 | BM9: 0 | BX9: SOFTGOODS_10FT X 1 | BY9: US_SOFTGOODS_10FT | BZ9: WATCH_10FT X 1 | CA9: US_WATCH_10FT | CD9: 1 | CE9: 1 | CG9: 0 | CH9: 0 | CI9: 0 | CJ9: 0 | CK9: 0 | CL9: 0 | CM9: 0 | CN9: 0 | CO9: 0 | CP9: 0 | CQ9: 0 | CR9: 0 | CS9: 0 | CT9: 0 | CU9: 0 | CV9: 0
A10: R007 | B10: MALL OF AMERICA | C10: BLOOMINGTON,MN | D10: US | E10: AMR | F10: US | 150' (2x75') | NSD 2.0 | R007 | Mall of America | G10: Avenues | H10: 1 | I10: 0 | J10: 0 | K10: N/A | W10: US_AIRPODS_10FT X 1 | X10: US_AIRPODS_10FT | Y10: AIRTAG_10FT X 1 | Z10: US_AIRTAG_10FT | AC10: APPLE_MUSIC_10FT X 1 | AD10: US_APPLE_MUSIC_10FT | AE10: TV_PLUS_10FT_FLEX_LP X 1 | AF10: US_TV_PLUS_10FT_FLEX_LP | AK10: ARCADE_10FT X 1 | AL10: US_ARCADE_10FT | AM10: CONNECTED_HOME_10FT X 1 | AN10: US_CONNECTED_HOME_10FT | AO10: ESSENTIALS_10FT_FLEXBAY X 1 | AP10: US_ESSENTIALS_10FT_FLEXBAY | AU10: FITNESS_PLUS_10FT X 1 | AV10: US_FITNESS_PLUS_10FT | AY10: US_GRAPHIC_PANEL_15FT X 2 | AZ10: US_GRAPHIC_PANEL_15FT+US_GRAPHIC_PANEL_15FT | BG10: 10FT (D.1) | BH10: US_IPHONE_10FT | BJ10: IPHONE_FEATURES_10FT X 1 | BK10: US_IPHONE_FEATURES_10FT | BL10: 1 | BM10: 0 | BX10: SOFTGOODS_10FT X 1 | BY10: US_SOFTGOODS_10FT | BZ10: WATCH_10FT X 1 | CA10: US_WATCH_10FT | CD10: 1 | CE10: 1 | CG10: 0 | CH10: 0 | CI10: 0 | CJ10: 0 | CK10: 0 | CL10: 0 | CM10: 0 | CN10: 0 | CO10: 0 | CP10: 0 | CQ10: 0 | CR10: 0 | CS10: 0 | CT10: 0 | CU10: 0 | CV10: 0
A11: R009 | B11: EASTON TOWN CENTER | C11: COLUMBUS,OH | D11: US | E11: AMR | F11: US | 2.18W (6.6W) | G11: Vintage | H11: 0 | I11: 0 | J11: 0 | K11: 1,2,3,4,5,6 | L11: X | M11: X | N11: X | O11: X | P11: X | Q11: X | AA11: AEA_FB3_2W_MF X 1 | AB11: R_US_AEA_FB3_2W | AO11: ESSENTIALS_4W_FB5_2W X 1 | AP11: R_US_ESSENTIALS_4W_FB5_2W | AS11: FB4 X 1 | AT11: R_US_FB4 | BG11: 6W | BH11: R_US_IPHONE_4W_FB2_2W | BT11: MUSIC_2W_FB1_2W X 1 | BU11: R_US_MUSIC_2W_FB1_2W | BX11: SOFTGOODS_2W_FB6_2W X 1 | BY11: R_US_SOFTGOODS_2W_FB6_2W | BZ11: R_US_WATCH_2W X 1 | CA11: R_US_WATCH_2W | CG11: 0 | CH11: 0 | CI11: 0 | CJ11: 0 | CK11: 0 | CL11: 0 | CM11: 0 | CN11: 0 | CO11: 0 | CP11: 0 | CQ11: 0 | CR11: 0 | CS11: 0 | CT11: 0 | CU11: 0 | CV11: 0
A12: R010 | B12: TYSON'S CORNER | C12: MC LEAN,VA | D12: US | E12: AMR | F12: US | 70' | 30' ER | Vin E | R010 | Tysons Corner | G12: Avenues | H12: 1 | I12: 0 | J12: 0 | W12: US_E_AIRPODS_10FT X 1 | X12: US_E_AIRPODS_10FT | AC12: US_E_APPLE_MUSIC_10FT X 1 | AD12: US_E_APPLE_MUSIC_10FT | AE12: US_E_TV_PLUS_FLEX_10FT X 1 | AF12: US_E_TV_PLUS_FLEX_10FT | AI12: US_PICKUP_COUNTER_D.2 X 1 | AJ12: US_PICKUP_COUNTER_D.2 | AY12: US_GRAPHIC_PANEL_10FT X 1 | AZ12: US_GRAPHIC_PANEL_10FT | BE12: US_E_IPAD_ACC_10FT X 1 | BF12: US_E_IPAD_ACC_10FT | BG12: 10FT (Vin E) | BH12: US_E_IPHONE_10FT | BI12: 1 | BN12: US_E_IPHONE_MAC_ACC_10FT X 1 | BO12: US_E_IPHONE_MAC_ACC_10FT | BZ12: US_E_WATCH_10FT_LEFT X 1+US_E_WATCH_10FT_RIGHT X 1+US_E_WATCH_STUDIO_10FT X 1 | CA12: US_E_WATCH_10FT_LEFT+US_E_WATCH_10FT_RIGHT+US_E_WATCH_STUDIO_10FT | CD12: 1 | CE12: 1 | CG12: 0 | CH12: 0 | CI12: 0 | CJ12: 0 | CK12: 0 | CL12: 0 | CM12: 0 | CN12: 0 | CO12: 0 | CP12: 0 | CQ12: 0 | CR12: 0 | CS12: 0 | CT12: 0 | CU12: 0 | CV12: 0
A13: R011 | B13: MARKETSTREET | C13: LYNNFIELD,MA | D13: US | E13: AMR | F13: US | 65' | NSD 2.0 | R011 | Market Street | G13: Avenues | H13: 1 | I13: 0 | J13: 0 | K13: N/A | W13: US_AIRPODS_10FT X 1 | X13: US_AIRPODS_10FT | AC13: APPLE_MUSIC_5FT X 1 | AD13: US_APPLE_MUSIC_5FT | AE13: TV_PLUS_5FT_FLEX_LP X 1 | AF13: US_TV_PLUS_5FT_FLEX_LP | AM13: CONNECTED_HOME_5FT X 1 | AN13: US_CONNECTED_HOME_5FT | AO13: ESSENTIALS_10FT X 1 | AP13: US_ESSENTIALS_10FT | BG13: 10FT (D.1) | BH13: US_IPHONE_10FT | BJ13: IPHONE_FEATURES_10FT X 1 | BK13: US_IPHONE_FEATURES_10FT | BL13: 1 | BM13: 0 | BX13: US_SOFTGOODS_AIRTAG_5FT X 1 | BY13: US_SOFTGOODS_AIRTAG_5FT | BZ13: WATCH_5FT X 1 | CA13: US_WATCH_5FT | CD13: 1 | CE13: 1 | CG13: 0 | CH13: 0 | CI13: 0 | CJ13: 0 | CK13: 0 | CL13: 0 | CM13: 0 | CN13: 0 | CO13: 0 | CP13: 0 | CQ13: 0 | CR13: 0 | CS13: 0 | CT13: 0 | CU13: 0 | CV13: 0
A14: R012 | B14: THE FALLS | C14: MIAMI,FL | D14: US | E14: AMR | F14: US | 2.12W (4.6W) | THE FALLS | G14: Vintage | H14: 0 | I14: 0 | J14: 0 | K14: 1,2,3,4 | L14: X | M14: X | N14: X | O14: X | AA14: AEA_FB3_2W X 1 | AB14: R_US_AEA_FB3_2W | AO14: ESSENTIALS_4W X 1 | AP14: R_US_ESSENTIALS_4W | AQ14: EXPRESS_PICKUP X 1 | AR14: US_EXPRESS_PICKUP | AS14: FB4 X 1 | AT14: R_US_FB4 | BG14: 4W | BH14: R_US_IPHONE_2W_FB2_2W | BT14: MUSIC_2W_FB1 X 1 | BU14: R_US_MUSIC_2W_FB1 | BX14: R_US_IPAD_2W X 1+R_US_MAC_1W X 1 | BY14: R_US_IPAD_2W+R_US_MAC_1W | BZ14: WATCH_1W X 1 | CA14: R_US_WATCH_1W | CG14: 0 | CH14: 0 | CI14: 0 | CJ14: 0 | CK14: 0 | CL14: 0 | CM14: 0 | CN14: 0 | CO14: 0 | CP14: 0 | CQ14: 0 | CR14: 0 | CS14: 0 | CT14: 0 | CU14: 0 | CV14: 0
A15: R013 | B15: TICE'S CORNER | C15: WOODCLIFF LAKE,NJ | D15: US | E15: AMR | F15: US | 120’ (2x60) | NSD 2.0 | R013 | Tice's Corner | G15: Avenues | H15: 2 | I15: 0 | J15: 0 | W15: US_AIRPODS_10FT X 1 | X15: US_AIRPODS_10FT | Y15: AIRTAG_5FT X 1 | Z15: US_AIRTAG_5FT | AC15: APPLE_MUSIC_10FT X 1 | AD15: US_APPLE_MUSIC_10FT | AE15: TV_PLUS_10FT_FLEX X 1 | AF15: US_TV_PLUS_10FT_FLEX | AI15: US_PICKUP_COUNTER_D.2 X 1 | AJ15: US_PICKUP_COUNTER_D.2 | AK15: ARCADE_5FT X 1 | AL15: US_ARCADE_5FT | AM15: CONNECTED_HOME_5FT X 1 | AN15: US_CONNECTED_HOME_5FT | AO15: ESSENTIALS_10FT_FLEXBAY X 1 | AP15: US_ESSENTIALS_10FT_FLEXBAY | AU15: FITNESS_PLUS_5FT X 1 | AV15: US_FITNESS_PLUS_5FT | AY15: US_GRAPHIC_PANEL_10FT X 2 | AZ15: US_GRAPHIC_PANEL_10FT+US_GRAPHIC_PANEL_10FT | BG15: 10FT (D.2) | BH15: US_IPHONE_10FT_FLEX | BI15: 1 | BJ15: IPHONE_FEATURES_10FT X 1 | BK15: US_IPHONE_FEATURES_10FT | BL15: 1 | BM15: 0 | BX15: SOFTGOODS_10FT X 1 | BY15: US_SOFTGOODS_10FT | BZ15: US_WATCH_EXTENDED_10FT X 1 | CA15: US_WATCH_EXTENDED_10FT | CD15: 1 | CE15: 1 | CG15: 0 | CH15: 0 | CI15: 0 | CJ15: 0 | CK15: 0 | CL15: 0 | CM15: 0 | CN15: 0 | CO15: 0 | CP15: 0 | CQ15: 0 | CR15: 0 | CS15: 0 | CT15: 0 | CU15: 0 | CV15: 0
A16: R014 | B16: BROADWAY PLAZA | C16: WALNUT CREEK,CA | D16: US | E16: AMR | F16: US | 100' | 2x40 1x20 | NSD 2.0 | R014 | Broadway Plaza | G16: Avenues | H16: 1 | I16: 0 | J16: 0 | K16: N/A | W16: US_AIRPODS_10FT X 1 | X16: US_AIRPODS_10FT | Y16: AIRTAG_5FT X 1 | Z16: US_AIRTAG_5FT | AC16: US_APPLE_MUSIC_HPM_10FT X 1 | AD16: US_APPLE_MUSIC_HPM_10FT | AE16: TV_PLUS_5FT_FLEX X 1 | AF16: US_TV_PLUS_5FT_FLEX | AK16: ARCADE_10FT X 1 | AL16: US_ARCADE_10FT | AM16: CONNECTED_HOME_5FT X 1 | AN16: US_CONNECTED_HOME_5FT | AO16: ESSENTIALS_10FT_FLEXBAY X 1 | AP16: US_ESSENTIALS_10FT_FLEXBAY | AU16: FITNESS_PLUS_5FT X 1 | AV16: US_FITNESS_PLUS_5FT | AY16: US_GRAPHIC_PANEL_10FT X 1 | AZ16: US_GRAPHIC_PANEL_10FT | BG16: 10FT (D.1) | BH16: US_IPHONE_10FT | BJ16: IPHONE_FEATURES_10FT X 1 | BK16: US_IPHONE_FEATURES_10FT | BL16: 1 | BM16: 0 | BX16: SOFTGOODS_5FT X 1 | BY16: US_SOFTGOODS_5FT | BZ16: WATCH_5FT X 1 | CA16: US_WATCH_5FT | CD16: 1 | CE16: 1 | CG16: 0 | CH16: 0 | CI16: 0 | CJ16: 0 | CK16: 0 | CL16: 0 | CM16: 0 | CN16: 0 | CO16: 0 | CP16: 0 | CQ16: 0 | CR16: 0 | CS16: 0 | CT16: 0 | CU16: 0 | CV16: 0
A17: R015 | B17: FASHION ISLAND | C17: NEWPORT BEACH,CA | D17: US | E17: AMR | F17: US | 2.18W (6.6W) | G17: Vintage | H17: 0 | I17: 0 | J17: 0 | K17: 1,2,3,4,5,6 | L17: X | M17: X | N17: X | O17: X | P17: X | Q17: X | AA17: AEA_FB3_2W_MF X 1 | AB17: R_US_AEA_FB3_2W | AO17: ESSENTIALS_4W_FB5_2W X 1 | AP17: R_US_ESSENTIALS_4W_FB5_2W | AS17: FB4 X 1 | AT17: R_US_FB4 | BG17: 6W | BH17: R_US_IPHONE_4W_FB2_2W | BT17: MUSIC_2W_FB1_2W X 1 | BU17: R_US_MUSIC_2W_FB1_2W | BX17: SOFTGOODS_2W_FB6_2W X 1 | BY17: R_US_SOFTGOODS_2W_FB6_2W | BZ17: R_US_WATCH_2W X 1 | CA17: R_US_WATCH_2W | CG17: 0 | CH17: 0 | CI17: 0 | CJ17: 0 | CK17: 0 | CL17: 0 | CM17: 0 | CN17: 0 | CO17: 0 | CP17: 0 | CQ17: 0 | CR17: 0 | CS17: 0 | CT17: 0 | CU17: 0 | CV17: 0
A18: R016 | B18: WALDEN GALLERIA | C18: BUFFALO,NY | D18: US | E18: AMR | F18: US | 90’ (1x55 1x35) | NSD 1.0 | R016 | Walden Galleria | G18: Avenues | H18: 0 | I18: 0 | J18: 0 | K18: N/A | W18: US_AIRPODS_10FT X 1 | X18: US_AIRPODS_10FT | AA18: AEA_5FT_A1 X 1 | AB18: US_AEA_5FT_A1 | AC18: US_APPLE_MUSIC_HPM_5FT X 1 | AD18: US_APPLE_MUSIC_HPM_5FT | AE18: TV_PLUS_5FT_FLEX_LP X 1 | AF18: US_TV_PLUS_5FT_FLEX_LP | AO18: ESSENTIALS_10FT X 1 | AP18: US_ESSENTIALS_10FT | AY18: US_GRAPHIC_PANEL_10FT X 1+US_GRAPHIC_PANEL_15FT X 1 | AZ18: US_GRAPHIC_PANEL_10FT+US_GRAPHIC_PANEL_15FT | BG18: 15FT (D.1) | BH18: US_IPHONE_15FT | BX18: US_SOFTGOODS_AIRTAG_10FT X 1 | BY18: US_SOFTGOODS_AIRTAG_10FT | BZ18: US_WATCH_EXTENDED_5FT X 1 | CA18: US_WATCH_EXTENDED_5FT | CD18: 1 | CE18: 1 | CG18: 0 | CH18: 0 | CI18: 0 | CJ18: 0 | CK18: 0 | CL18: 0 | CM18: 0 | CN18: 0 | CO18: 0 | CP18: 0 | CQ18: 0 | CR18: 0 | CS18: 0 | CT18: 0 | CU18: 0 | CV18: 0
A19: R017 | B19: CROSSGATES | C19: ALBANY,NY | D19: US | E19: AMR | F19: US | 110’ (2x55) | NSD 1.0 | R017 | Crossgates | G19: Avenues | H19: 0 | I19: 0 | J19: 0 | K19: N/A | W19: US_AIRPODS_10FT X 1 | X19: US_AIRPODS_10FT | AA19: AEA_5FT X 1+US_ESSENTIALS_5FT_IPHONE X 1 | AB19: US_AEA_5FT+US_ESSENTIALS_5FT_IPHONE | AC19: US_APPLE_MUSIC_HPM_5FT X 1 | AD19: US_APPLE_MUSIC_HPM_5FT | AE19: TV_PLUS_5FT_FLEX_LP X 1 | AF19: US_TV_PLUS_5FT_FLEX_LP | AO19: ESSENTIALS_10FT X 1 | AP19: US_ESSENTIALS_10FT | AY19: US_GRAPHIC_PANEL_15FT X 2+US_GRAPHIC_PANEL_5FT X 2 | AZ19: US_GRAPHIC_PANEL_15FT+US_GRAPHIC_PANEL_15FT+US_GRAPHIC_PANEL_5FT+US_GRAPHIC_PANEL_5FT | BG19: 15FT (D.1) | BH19: US_IPHONE_15FT | BX19: US_SOFTGOODS_AIRTAG_10FT X 1 | BY19: US_SOFTGOODS_AIRTAG_10FT | BZ19: WATCH_5FT X 1 | CA19: US_WATCH_5FT | CD19: 1 | CE19: 1 | CG19: 0 | CH19: 0 | CI19: 0 | CJ19: 0 | CK19: 0 | CL19: 0 | CM19: 0 | CN19: 0 | CO19: 0 | CP19: 0 | CQ19: 0 | CR19: 0 | CS19: 0 | CT19: 0 | CU19: 0 | CV19: 0
A20: R018 | B20: WOODFIELD MALL | C20: SCHAUMBURG,IL | D20: US | E20: AMR | F20: US | 110' (2x55) | NSD 2.0 | R018 Woodfield Mall | G20: Avenues | H20: 1 | I20: 0 | J20: 0 | K20: N/A | W20: US_AIRPODS_10FT X 1 | X20: US_AIRPODS_10FT | Y20: AIRTAG_5FT X 1 | Z20: US_AIRTAG_5FT | AC20: APPLE_MUSIC_10FT X 1 | AD20: US_APPLE_MUSIC_10FT | AE20: TV_PLUS_5FT_FLEX_LP X 1 | AF20: US_TV_PLUS_5FT_FLEX_LP | AK20: ARCADE_10FT X 1 | AL20: US_ARCADE_10FT | AM20: CONNECTED_HOME_10FT X 1 | AN20: US_CONNECTED_HOME_10FT | AO20: ESSENTIALS_10FT X 1 | AP20: US_ESSENTIALS_10FT | AU20: FITNESS_PLUS_10FT X 1 | AV20: US_FITNESS_PLUS_10FT | BG20: 10FT (D.1) | BH20: US_IPHONE_10FT | BJ20: IPHONE_FEATURES_10FT X 1 | BK20: US_IPHONE_FEATURES_10FT | BL20: 1 | BM20: 0 | BX20: SOFTGOODS_10FT X 1 | BY20: US_SOFTGOODS_10FT | BZ20: WATCH_10FT X 1 | CA20: US_WATCH_10FT | CD20: 1 | CE20: 1 | CG20: 0 | CH20: 0 | CI20: 0 | CJ20: 0 | CK20: 0 | CL20: 0 | CM20: 0 | CN20: 0 | CO20: 0 | CP20: 0 | CQ20: 0 | CR20: 0 | CS20: 0 | CT20: 0 | CU20: 0 | CV20: 0
A21: R019 | B21: INT'L PLAZA | C21: TAMPA,FL | D21: US | E21: AMR | F21: US | 2.14 | R019 | International Plaza | G21: Vintage | H21: 0 | I21: 0 | J21: 0 | K21: 1,2,3,4 | L21: X | M21: X | N21: X | O21: X | AA21: AEA_FB3_2W X 1 | AB21: R_US_AEA_FB3_2W | AO21: ESSENTIALS_4W X 1 | AP21: R_US_ESSENTIALS_4W | AS21: FB4 X 1 | AT21: R_US_FB4 | BG21: 6W | BH21: R_US_IPHONE_4W_FB2_2W | BT21: MUSIC_2W_FB1_2W X 1 | BU21: R_US_MUSIC_2W_FB1_2W | BX21: R_US_IPAD_2W X 1+R_US_MAC_1W X 1 | BY21: R_US_IPAD_2W+R_US_MAC_1W | BZ21: R_US_WATCH_EXTENDED_1W X 1 | CA21: R_US_WATCH_EXTENDED_1W | CG21: 0 | CH21: 0 | CI21: 0 | CJ21: 0 | CK21: 0 | CL21: 0 | CM21: 0 | CN21: 0 | CO21: 0 | CP21: 0 | CQ21: 0 | CR21: 0 | CS21: 0 | CT21: 0 | CU21: 0 | CV21: 0
A22: R020 | B22: SADDLE CREEK | C22: GERMANTOWN,TN | D22: US | E22: AMR | F22: US | 100’ (2x50) | NSD 1.0 | Express | R020 | Saddle Creek | G22: Avenues | H22: 0 | I22: 0 | J22: 0 | K22: N/A | W22: US_AIRPODS_10FT X 1 | X22: US_AIRPODS_10FT | AA22: AEA_10FT_SPLIT X 1 | AB22: US_AEA_10FT_SPLIT | AC22: US_APPLE_MUSIC_HPM_5FT X 1 | AD22: US_APPLE_MUSIC_HPM_5FT | AE22: TV_PLUS_5FT_FLEX_LP X 1 | AF22: US_TV_PLUS_5FT_FLEX_LP | AO22: ESSENTIALS_10FT X 1 | AP22: US_ESSENTIALS_10FT | AQ22: EXPRESS_PICKUP X 1 | AR22: US_EXPRESS_PICKUP | AY22: US_GRAPHIC_PANEL_10FT X 1+US_GRAPHIC_PANEL_15FT X 1+US_GRAPHIC_PANEL_5FT X 2 | AZ22: US_GRAPHIC_PANEL_10FT+US_GRAPHIC_PANEL_15FT+US_GRAPHIC_PANEL_5FT+US_GRAPHIC_PANEL_5FT | BG22: 10FT (D.1) | BH22: US_IPHONE_10FT | BX22: US_SOFTGOODS_AIRTAG_10FT X 1 | BY22: US_SOFTGOODS_AIRTAG_10FT | BZ22: WATCH_5FT X 1 | CA22: US_WATCH_5FT | CD22: 1 | CE22: 1 | CG22: 0 | CH22: 0 | CI22: 0 | CJ22: 0 | CK22: 0 | CL22: 0 | CM22: 0 | CN22: 0 | CO22: 0 | CP22: 0 | CQ22: 0 | CR22: 0 | CS22: 0 | CT22: 0 | CU22: 0 | CV22: 0
A23: R021 | B23: CAMBRIDGESIDE | C23: CAMBRIDGE,MA | D23: US | E23: AMR | F23: US | 110' (2x55) | NSD 2.0 | R021 Cambridgeside | G23: Avenues | H23: 1 | I23: 0 | J23: 0 | K23: N/A | W23: US_AIRPODS_10FT X 1 | X23: US_AIRPODS_10FT | Y23: AIRTAG_5FT X 1 | Z23: US_AIRTAG_5FT | AC23: APPLE_MUSIC_10FT X 1 | AD23: US_APPLE_MUSIC_10FT | AE23: TV_PLUS_5FT_FLEX_LP X 1 | AF23: US_TV_PLUS_5FT_FLEX_LP | AK23: ARCADE_10FT X 1 | AL23: US_ARCADE_10FT | AM23: CONNECTED_HOME_10FT X 1 | AN23: US_CONNECTED_HOME_10FT | AO23: ESSENTIALS_10FT X 1 | AP23: US_ESSENTIALS_10FT | AU23: FITNESS_PLUS_10FT X 1 | AV23: US_FITNESS_PLUS_10FT | BG23: 10FT (D.1) | BH23: US_IPHONE_10FT | BJ23: IPHONE_FEATURES_10FT X 1 | BK23: US_IPHONE_FEATURES_10FT | BL23: 1 | BM23: 0 | BX23: SOFTGOODS_10FT X 1 | BY23: US_SOFTGOODS_10FT | BZ23: WATCH_10FT X 1 | CA23: US_WATCH_10FT | CD23: 1 | CE23: 1 | CG23: 0 | CH23: 0 | CI23: 0 | CJ23: 0 | CK23: 0 | CL23: 0 | CM23: 0 | CN23: 0 | CO23: 0 | CP23: 0 | CQ23: 0 | CR23: 0 | CS23: 0 | CT23: 0 | CU23: 0 | CV23: 0
A24: R022 | B24: ROSEDALE CENTER | C24: ROSEVILLE,MN | D24: US | E24: AMR | F24: US | 2.16W | 2.LT | ASA UPDATE | G24: Vintage | H24: 0 | I24: 0 | J24: 0 | K24: 1,2,3,4,5,6 | L24: X | M24: X | N24: X | O24: X | P24: X | Q24: X | AA24: AEA_FB3_2W X 1 | AB24: R_US_AEA_FB3_2W | AO24: ESSENTIALS_2W_FB5_2W X 1 | AP24: R_US_ESSENTIALS_2W_FB5_2W | AS24: FB4 X 1 | AT24: R_US_FB4 | BG24: 6W | BH24: R_US_IPHONE_2W_FB6_2W_FB2_2W | BT24: MUSIC_2W_FB1_2W X 1 | BU24: R_US_MUSIC_2W_FB1_2W | BX24: R_US_IPAD_2W X 1+R_US_MAC_1W X 1 | BY24: R_US_IPAD_2W+R_US_MAC_1W | BZ24: WATCH_1W X 1 | CA24: R_US_WATCH_1W | CG24: 0 | CH24: 0 | CI24: 0 | CJ24: 0 | CK24: 0 | CL24: 0 | CM24: 0 | CN24: 0 | CO24: 0 | CP24: 0 | CQ24: 0 | CR24: 0 | CS24: 0 | CT24: 0 | CU24: 0 | CV24: 0
A25: R023 | B25: NORTHRIDGE | C25: NORTHRIDGE,CA | D25: US | E25: AMR | F25: US | 2.12W | G25: Vintage | H25: 0 | I25: 0 | J25: 0 | K25: 1,2,3,4 | L25: X | M25: X | N25: X | O25: X | AA25: AEA_FB3_2W X 1 | AB25: R_US_AEA_FB3_2W | AO25: ESSENTIALS_4W X 1 | AP25: R_US_ESSENTIALS_4W | AS25: FB4 X 1 | AT25: R_US_FB4 | BG25: 4W | BH25: R_US_IPHONE_2W_FB2_2W | BT25: MUSIC_2W_FB1 X 1 | BU25: R_US_MUSIC_2W_FB1 | BX25: R_US_IPAD_2W X 1+R_US_MAC_1W X 1 | BY25: R_US_IPAD_2W+R_US_MAC_1W | BZ25: WATCH_1W X 1 | CA25: R_US_WATCH_1W | CG25: 0 | CH25: 0 | CI25: 0 | CJ25: 0 | CK25: 0 | CL25: 0 | CM25: 0 | CN25: 0 | CO25: 0 | CP25: 0 | CQ25: 0 | CR25: 0 | CS25: 0 | CT25: 0 | CU25: 0 | CV25: 0
A26: R024 | B26: WELLINGTON GREEN | C26: WELLINGTON,FL | D26: US | E26: AMR | F26: US | 2.12W | G26: Vintage | H26: 0 | I26: 0 | J26: 0 | K26: 1,2,3,4 | L26: X | M26: X | N26: X | O26: X | AA26: AEA_FB3_2W X 1 | AB26: R_US_AEA_FB3_2W | AO26: ESSENTIALS_4W X 1 | AP26: R_US_ESSENTIALS_4W | AS26: FB4 X 1 | AT26: R_US_FB4 | BG26: 4W | BH26: R_US_IPHONE_2W_FB2_2W | BT26: MUSIC_2W_FB1 X 1 | BU26: R_US_MUSIC_2W_FB1 | BX26: R_US_IPAD_2W X 1+R_US_MAC_1W X 1 | BY26: R_US_IPAD_2W+R_US_MAC_1W | BZ26: WATCH_1W X 1 | CA26: R_US_WATCH_1W | CG26: 0 | CH26: 0 | CI26: 0 | CJ26: 0 | CK26: 0 | CL26: 0 | CM26: 0 | CN26: 0 | CO26: 0 | CP26: 0 | CQ26: 0 | CR26: 0 | CS26: 0 | CT26: 0 | CU26: 0 | CV26: 0
A27: R025 | B27: WESTFARMS | C27: FARMINGTON,CT | D27: US | E27: AMR | F27: US | 2.14W V1 | G27: Vintage | H27: 0 | I27: 0 | J27: 0 | K27: 1,2,3,4 | L27: X | M27: X | N27: X | O27: X | AA27: AEA_FB3_2W X 1 | AB27: R_US_AEA_FB3_2W | AO27: ESSENTIALS_4W X 1 | AP27: R_US_ESSENTIALS_4W | AS27: FB4 X 1 | AT27: R_US_FB4 | BG27: 6W | BH27: R_US_IPHONE_4W_FB2_2W | BT27: MUSIC_2W_FB1_2W X 1 | BU27: R_US_MUSIC_2W_FB1_2W | BX27: R_US_IPAD_2W X 1+R_US_MAC_1W X 1 | BY27: R_US_IPAD_2W+R_US_MAC_1W | BZ27: WATCH_1W X 1 | CA27: R_US_WATCH_1W | CG27: 0 | CH27: 0 | CI27: 0 | CJ27: 0 | CK27: 0 | CL27: 0 | CM27: 0 | CN27: 0 | CO27: 0 | CP27: 0 | CQ27: 0 | CR27: 0 | CS27: 0 | CT27: 0 | CU27: 0 | CV27: 0
A28: R026 | B28: CHANDLER FASHION CENTER | C28: CHANDLER,AZ | D28: US | E28: AMR | F28: US | 150’ (2x75) | NSD 2.0 | R026 | Chandler Fashion Center | G28: Avenues | H28: 1 | I28: 0 | J28: 0 | K28: N/A | W28: US_AIRPODS_10FT X 1 | X28: US_AIRPODS_10FT | Y28: AIRTAG_10FT X 1 | Z28: US_AIRTAG_10FT | AC28: APPLE_MUSIC_10FT X 1 | AD28: US_APPLE_MUSIC_10FT | AE28: TV_PLUS_10FT_FLEX_LP X 1 | AF28: US_TV_PLUS_10FT_FLEX_LP | AK28: ARCADE_10FT X 1 | AL28: US_ARCADE_10FT | AM28: CONNECTED_HOME_10FT X 1 | AN28: US_CONNECTED_HOME_10FT | AO28: ESSENTIALS_10FT X 1 | AP28: US_ESSENTIALS_10FT | AU28: FITNESS_PLUS_10FT X 1 | AV28: US_FITNESS_PLUS_10FT | AY28: US_GRAPHIC_PANEL_15FT X 2 | AZ28: US_GRAPHIC_PANEL_15FT+US_GRAPHIC_PANEL_15FT | BG28: 10FT (D.1) | BH28: US_IPHONE_10FT | BJ28: IPHONE_FEATURES_10FT X 1 | BK28: US_IPHONE_FEATURES_10FT | BL28: 1 | BM28: 0 | BX28: SOFTGOODS_10FT X 1 | BY28: US_SOFTGOODS_10FT | BZ28: WATCH_10FT X 1 | CA28: US_WATCH_10FT | CD28: 1 | CE28: 1 | CG28: 0 | CH28: 0 | CI28: 0 | CJ28: 0 | CK28: 0 | CL28: 0 | CM28: 0 | CN28: 0 | CO28: 0 | CP28: 0 | CQ28: 0 | CR28: 0 | CS28: 0 | CT28: 0 | CU28: 0 | CV28: 0
A29: R027 | B29: ROCKINGHAM PARK | C29: SALEM,NH | D29: US | E29: AMR | F29: US | 2.18W | 2.LT | G29: Vintage | H29: 0 | I29: 0 | J29: 0 | K29: 1,2,3,4,5,6 | L29: X | M29: X | N29: X | O29: X | P29: X | Q29: X | AA29: AEA_FB3_2W_MF X 1 | AB29: R_US_AEA_FB3_2W | AO29: ESSENTIALS_4W_FB5_2W X 1 | AP29: R_US_ESSENTIALS_4W_FB5_2W | AS29: FB4 X 1 | AT29: R_US_FB4 | BG29: 6W | BH29: R_US_IPHONE_4W_FB2_2W | BT29: MUSIC_2W_FB1_2W X 1 | BU29: R_US_MUSIC_2W_FB1_2W | BX29: SOFTGOODS_2W_FB6_2W X 1 | BY29: R_US_SOFTGOODS_2W_FB6_2W | BZ29: R_US_WATCH_2W X 1 | CA29: R_US_WATCH_2W | CG29: 0 | CH29: 0 | CI29: 0 | CJ29: 0 | CK29: 0 | CL29: 0 | CM29: 0 | CN29: 0 | CO29: 0 | CP29: 0 | CQ29: 0 | CR29: 0 | CS29: 0 | CT29: 0 | CU29: 0 | CV29: 0
